Workbook

Sheet DATA HAFALAN
A1: PETA DATA HAFALAN 1 MUHARRAM 1448 H
A5: NO | B5: NAMA | C5: JUMLAH | D5: 1 | E5: 2 | F5: 3 | G5: 4 | H5: 5 | I5: 6 | J5: 7 | K5: 8 | L5: 9 | M5: 10 | N5: 11 | O5: 12 | P5: 13 | Q5: 14 | R5: 15 | S5: 16 | T5: 17 | U5: 18 | V5: 19 | W5: 20 | X5: 21 | Y5: 22 | Z5: 23 | AA5: 24 | AB5: 25 | AC5: 26 | AD5: 27 | AE5: 28 | AF5: 29 | AG5: 30
A6: 1 | B6: AYI KOSIM HATIMI | C6: =COUNTIF(D6:AG6,"TRUE") -> 30 | D6: =TRUE() -> TRUE | E6: =TRUE() -> TRUE | F6: =TRUE() -> TRUE | G6: =TRUE() -> TRUE | H6: =TRUE() -> TRUE | I6: =TRUE() -> TRUE | J6: =TRUE() -> TRUE | K6: =TRUE() -> TRUE | ... AG6: =TRUE() -> TRUE
A7: 2 | B7: ABRURRAHMAN AFANDI | C7: =COUNTIF(D7:AG7,"TRUE") -> 30 | D7: =TRUE() -> TRUE | E7: =TRUE() -> TRUE | F7: =TRUE() -> TRUE | G7: =TRUE() -> TRUE | H7: =TRUE() -> TRUE | I7: =TRUE() -> TRUE | J7: =TRUE() -> TRUE | K7: =TRUE() -> TRUE | ... AG7: =TRUE() -> TRUE
A8: 3 | B8: CECEP ABDULATIF | C8: =COUNTIF(D8:AG8,"TRUE") -> 30 | D8: =TRUE() -> TRUE | E8: =TRUE() -> TRUE | F8: =TRUE() -> TRUE | G8: =TRUE() -> TRUE | H8: =TRUE() -> TRUE | I8: =TRUE() -> TRUE | J8: =TRUE() -> TRUE | K8: =TRUE() -> TRUE | ... AG8: =TRUE() -> TRUE
A9: 4 | B9: DONI SUPRIATNA | C9: =COUNTIF(D9:AG9,"TRUE") -> 30 | D9: =TRUE() -> TRUE | E9: =TRUE() -> TRUE | F9: =TRUE() -> TRUE | G9: =TRUE() -> TRUE | H9: =TRUE() -> TRUE | I9: =TRUE() -> TRUE | J9: =TRUE() -> TRUE | K9: =TRUE() -> TRUE | ... AG9: =TRUE() -> TRUE
A10: 5 | B10: ZAKY AZHARI | C10: =COUNTIF(D10:AG10,"TRUE") -> 30 | D10: =TRUE() -> TRUE | E10: =TRUE() -> TRUE | F10: =TRUE() -> TRUE | G10: =TRUE() -> TRUE | H10: =TRUE() -> TRUE | I10: =TRUE() -> TRUE | J10: =TRUE() -> TRUE | K10: =TRUE() -> TRUE | ... AG10: =TRUE() -> TRUE
A11: 6 | B11: MUHAMMAD FAUZIL ADZIM | C11: =COUNTIF(D11:AG11,"TRUE") -> 30 | D11: =TRUE() -> TRUE | E11: =TRUE() -> TRUE | F11: =TRUE() -> TRUE | G11: =TRUE() -> TRUE | H11: =TRUE() -> TRUE | I11: =TRUE() -> TRUE | J11: =TRUE() -> TRUE | K11: =TRUE() -> TRUE | ... AG11: =TRUE() -> TRUE
A12: 7 | B12: MUHAMMAD DZIKRI HUSAENI | C12: =COUNTIF(D12:AG12,"TRUE") -> 18 | D12: =TRUE() -> TRUE | E12: =TRUE() -> TRUE | F12: =TRUE() -> TRUE | G12: =TRUE() -> TRUE | H12: =TRUE() -> TRUE | I12: =TRUE() -> TRUE | J12: =TRUE() -> TRUE | K12: =TRUE() -> TRUE | ... P12: =TRUE() -> TRUE | Q12: =FALSE() -> FALSE | R12: =FALSE() -> FALSE | S12: =FALSE() -> FALSE | T12: =FALSE() -> FALSE | U12: =FALSE() -> FALSE | V12: =FALSE() -> FALSE | W12: =FALSE() -> FALSE | X12: =FALSE() -> FALSE | ... AB12: =FALSE() -> FALSE | AC12: =TRUE() -> TRUE | AD12: =TRUE() -> TRUE | AE12: =TRUE() -> TRUE | AF12: =TRUE() -> TRUE | AG12: =TRUE() -> TRUE
A13: 8 | B13: ABDUL KHOLIQ | C13: =COUNTIF(D13:AG13,"TRUE") -> 14 | D13: =TRUE() -> TRUE | E13: =TRUE() -> TRUE | F13: =TRUE() -> TRUE | G13: =TRUE() -> TRUE | H13: =TRUE() -> TRUE | I13: =TRUE() -> TRUE | J13: =TRUE() -> TRUE | K13: =TRUE() -> TRUE | L13: =TRUE() -> TRUE | M13: =FALSE() -> FALSE | N13: =FALSE() -> FALSE | O13: =FALSE() -> FALSE | P13: =FALSE() -> FALSE | Q13: =FALSE() -> FALSE | R13: =FALSE() -> FALSE | S13: =FALSE() -> FALSE | T13: =FALSE() -> FALSE | ... AB13: =FALSE() -> FALSE | AC13: =TRUE() -> TRUE | AD13: =TRUE() -> TRUE | AE13: =TRUE() -> TRUE | AF13: =TRUE() -> TRUE | AG13: =TRUE() -> TRUE
A14: 9 | B14: IYAN FARID | C14: =COUNTIF(D14:AG14,"TRUE") -> 13 | D14: =TRUE() -> TRUE | E14: =TRUE() -> TRUE | F14: =TRUE() -> TRUE | G14: =TRUE() -> TRUE | H14: =TRUE() -> TRUE | I14: =TRUE() -> TRUE | J14: =TRUE() -> TRUE | K14: =TRUE() -> TRUE | ... O14: =TRUE() -> TRUE | P14: =FALSE() -> FALSE | Q14: =FALSE() -> FALSE | R14: =FALSE() -> FALSE | S14: =FALSE() -> FALSE | T14: =FALSE() -> FALSE | U14: =FALSE() -> FALSE | V14: =FALSE() -> FALSE | W14: =FALSE() -> FALSE | ... AF14: =FALSE() -> FALSE | AG14: =TRUE() -> TRUE
A15: 10 | B15: ZAENI NURIL HIKAM | C15: =COUNTIF(D15:AG15,"TRUE") -> 12 | D15: =TRUE() -> TRUE | E15: =TRUE() -> TRUE | F15: =TRUE() -> TRUE | G15: =TRUE() -> TRUE | H15: =TRUE() -> TRUE | I15: =TRUE() -> TRUE | J15: =TRUE() -> TRUE | K15: =TRUE() -> TRUE | ... M15: =TRUE() -> TRUE | N15: =FALSE() -> FALSE | O15: =FALSE() -> FALSE | P15: =FALSE() -> FALSE | Q15: =FALSE() -> FALSE | R15: =FALSE() -> FALSE | S15: =FALSE() -> FALSE | T15: =FALSE() -> FALSE | U15: =FALSE() -> FALSE | ... AE15: =FALSE() -> FALSE | AF15: =TRUE() -> TRUE | AG15: =TRUE() -> TRUE
A16: 11 | B16: LUCKY KURNIAWAN | C16: =COUNTIF(D16:AG16,"TRUE") -> 12 | D16: =TRUE() -> TRUE | E16: =TRUE() -> TRUE | F16: =TRUE() -> TRUE | G16: =TRUE() -> TRUE | H16: =TRUE() -> TRUE | I16: =TRUE() -> TRUE | J16: =TRUE() -> TRUE | K16: =TRUE() -> TRUE | ... M16: =TRUE() -> TRUE | N16: =FALSE() -> FALSE | O16: =FALSE() -> FALSE | P16: =FALSE() -> FALSE | Q16: =FALSE() -> FALSE | R16: =FALSE() -> FALSE | S16: =FALSE() -> FALSE | T16: =FALSE() -> FALSE | U16: =FALSE() -> FALSE | ... AE16: =FALSE() -> FALSE | AF16: =TRUE() -> TRUE | AG16: =TRUE() -> TRUE
A17: 12 | B17: MUHAMMAD RAFIK MUHARAM | C17: =COUNTIF(D17:AG17,"TRUE") -> 12 | D17: =TRUE() -> TRUE | E17: =TRUE() -> TRUE | F17: =TRUE() -> TRUE | G17: =TRUE() -> TRUE | H17: =TRUE() -> TRUE | I17: =TRUE() -> TRUE | J17: =TRUE() -> TRUE | K17: =FALSE() -> FALSE | L17: =FALSE() -> FALSE | M17: =FALSE() -> FALSE | N17: =FALSE() -> FALSE | O17: =FALSE() -> FALSE | P17: =FALSE() -> FALSE | Q17: =FALSE() -> FALSE | R17: =FALSE() -> FALSE | ... AB17: =FALSE() -> FALSE | AC17: =TRUE() -> TRUE | AD17: =TRUE() -> TRUE | AE17: =TRUE() -> TRUE | AF17: =TRUE() -> TRUE | AG17: =TRUE() -> TRUE
A18: 13 | B18: UMAR ABDUL MALIK | C18: =COUNTIF(D18:AG18,"TRUE") -> 11 | D18: =TRUE() -> TRUE | E18: =TRUE() -> TRUE | F18: =TRUE() -> TRUE | G18: =TRUE() -> TRUE | H18: =TRUE() -> TRUE | I18: =TRUE() -> TRUE | J18: =FALSE() -> FALSE | K18: =FALSE() -> FALSE | L18: =FALSE() -> FALSE | M18: =FALSE() -> FALSE | N18: =FALSE() -> FALSE | O18: =FALSE() -> FALSE | P18: =FALSE() -> FALSE | Q18: =FALSE() -> FALSE | ... AB18: =FALSE() -> FALSE | AC18: =TRUE() -> TRUE | AD18: =TRUE() -> TRUE | AE18: =TRUE() -> TRUE | AF18: =TRUE() -> TRUE | AG18: =TRUE() -> TRUE
A19: 14 | B19: AHMAD HAFIDZ ALHAWARI | C19: =COUNTIF(D19:AG19,"TRUE") -> 10 | D19: =TRUE() -> TRUE | E19: =TRUE() -> TRUE | F19: =TRUE() -> TRUE | G19: =TRUE() -> TRUE | H19: =TRUE() -> TRUE | I19: =TRUE() -> TRUE | J19: =TRUE() -> TRUE | K19: =TRUE() -> TRUE | L19: =TRUE() -> TRUE | M19: =FALSE() -> FALSE | N19: =FALSE() -> FALSE | O19: =FALSE() -> FALSE | P19: =FALSE() -> FALSE | Q19: =FALSE() -> FALSE | R19: =FALSE() -> FALSE | S19: =FALSE() -> FALSE | T19: =FALSE() -> FALSE | ... AF19: =FALSE() -> FALSE | AG19: =TRUE() -> TRUE
A20: 15 | B20: MUHAMMAD FAUZAN | C20: =COUNTIF(D20:AG20,"TRUE") -> 10 | D20: =TRUE() -> TRUE | E20: =TRUE() -> TRUE | F20: =TRUE() -> TRUE | G20: =TRUE() -> TRUE | H20: =TRUE() -> TRUE | I20: =TRUE() -> TRUE | J20: =TRUE() -> TRUE | K20: =TRUE() -> TRUE | L20: =FALSE() -> FALSE | M20: =FALSE() -> FALSE | N20: =FALSE() -> FALSE | O20: =FALSE() -> FALSE | P20: =FALSE() -> FALSE | Q20: =FALSE() -> FALSE | R20: =FALSE() -> FALSE | S20: =FALSE() -> FALSE | ... AE20: =FALSE() -> FALSE | AF20: =TRUE() -> TRUE | AG20: =TRUE() -> TRUE
A21: 16 | B21: AKBAR RAMADAN | C21: =COUNTIF(D21:AG21,"TRUE") -> 9 | D21: =TRUE() -> TRUE | E21: =TRUE() -> TRUE | F21: =TRUE() -> TRUE | G21: =TRUE() -> TRUE | H21: =TRUE() -> TRUE | I21: =TRUE() -> TRUE | J21: =TRUE() -> TRUE | K21: =FALSE() -> FALSE | L21: =FALSE() -> FALSE | M21: =FALSE() -> FALSE | N21: =FALSE() -> FALSE | O21: =FALSE() -> FALSE | P21: =FALSE() -> FALSE | Q21: =FALSE() -> FALSE | R21: =FALSE() -> FALSE | ... AE21: =FALSE() -> FALSE | AF21: =TRUE() -> TRUE | AG21: =TRUE() -> TRUE
A22: 17 | B22: ABIDZAR ALGHIFARI | C22: =COUNTIF(D22:AG22,"TRUE") -> 8 | D22: =TRUE() -> TRUE | E22: =TRUE() -> TRUE | F22: =TRUE() -> TRUE | G22: =TRUE() -> TRUE | H22: =TRUE() -> TRUE | I22: =TRUE() -> TRUE | J22: =FALSE() -> FALSE | K22: =FALSE() -> FALSE | L22: =FALSE() -> FALSE | M22: =FALSE() -> FALSE | N22: =FALSE() -> FALSE | O22: =FALSE() -> FALSE | P22: =FALSE() -> FALSE | Q22: =FALSE() -> FALSE | ... AE22: =FALSE() -> FALSE | AF22: =TRUE() -> TRUE | AG22: =TRUE() -> TRUE
A23: 18 | B23: KAFY MUHAMMAD AZIZY | C23: =COUNTIF(D23:AG23,"TRUE") -> 7 | D23: =TRUE() -> TRUE | E23: =TRUE() -> TRUE | F23: =TRUE() -> TRUE | G23: =TRUE() -> TRUE | H23: =TRUE() -> TRUE | I23: =FALSE() -> FALSE | J23: =FALSE() -> FALSE | K23: =FALSE() -> FALSE | L23: =FALSE() -> FALSE | M23: =FALSE() -> FALSE | N23: =FALSE() -> FALSE | O23: =FALSE() -> FALSE | P23: =FALSE() -> FALSE | ... AE23: =FALSE() -> FALSE | AF23: =TRUE() -> TRUE | AG23: =TRUE() -> TRUE
A24: 19 | B24: MUHAMMAD MUNAWWAR KHOLIL | C24: =COUNTIF(D24:AG24,"TRUE") -> 4 | D24: =FALSE() -> FALSE | E24: =FALSE() -> FALSE | F24: =FALSE() -> FALSE | G24: =FALSE() -> FALSE | H24: =FALSE() -> FALSE | I24: =FALSE() -> FALSE | J24: =FALSE() -> FALSE | K24: =FALSE() -> FALSE | ... AC24: =FALSE() -> FALSE | AD24: =TRUE() -> TRUE | AE24: =TRUE() -> TRUE | AF24: =TRUE() -> TRUE | AG24: =TRUE() -> TRUE
A25: 20 | B25: ALWI | C25: =COUNTIF(D25:AG25,"TRUE") -> 3 | D25: =TRUE() -> TRUE | E25: =FALSE() -> FALSE | F25: =FALSE() -> FALSE | G25: =FALSE() -> FALSE | H25: =FALSE() -> FALSE | I25: =FALSE() -> FALSE | J25: =FALSE() -> FALSE | K25: =FALSE() -> FALSE | L25: =FALSE() -> FALSE | ... AE25: =FALSE() -> FALSE | AF25: =TRUE() -> TRUE | AG25: =TRUE() -> TRUE
A26: 21 | B26: PIRMAN | C26: =COUNTIF(D26:AG26,"TRUE") -> 1 | D26: =FALSE() -> FALSE | E26: =FALSE() -> FALSE | F26: =FALSE() -> FALSE | G26: =FALSE() -> FALSE | H26: =FALSE() -> FALSE | I26: =FALSE() -> FALSE | J26: =FALSE() -> FALSE | K26: =FALSE() -> FALSE | ... AF26: =FALSE() -> FALSE | AG26: =TRUE() -> TRUE
A27: 22 | B27: MUHAMMAD DENMAR NABAWI | C27: =COUNTIF(D27:AG27,"TRUE") -> 1 | D27: =FALSE() -> FALSE | E27: =FALSE() -> FALSE | F27: =FALSE() -> FALSE | G27: =FALSE() -> FALSE | H27: =FALSE() -> FALSE | I27: =FALSE() -> FALSE | J27: =FALSE() -> FALSE | K27: =FALSE() -> FALSE | ... AF27: =FALSE() -> FALSE | AG27: =TRUE() -> TRUE

Sheet target
A1: TARGET PENCAPAIAN SEBELUM DIKLAT ROBI'UL AWWAL
A5: NO | B5: NAMA | C5: TARGET | D5: PENCAPAIAN | E5: EVALUASI PENCAPAIAN
A6: 1 | B6: ='DATA HAFALAN'!B6 -> AYI KOSIM HATIMI | C6: sima'an 15 Juz ( juz 1 - 15 ) | E6: =IF(D6>=15,"TERCAPAI","BELUM TERCAPAI") -> BELUM TERCAPAI
A7: 2 | B7: ='DATA HAFALAN'!B7 -> ABRURRAHMAN AFANDI | C7: sima'an 10 Juz ( juz 1 - 5, juz 26 - 30 ) | E7: =IF(D7>=10,"TERCAPAI","BELUM TERCAPAI") -> BELUM TERCAPAI
A8: 3 | B8: ='DATA HAFALAN'!B8 -> CECEP ABDULATIF | C8: sima'an 10 Juz ( juz 1- 10 ) | E8: =IF(D8>=10,"TERCAPAI","BELUM TERCAPAI") -> BELUM TERCAPAI
A9: 4 | B9: ='DATA HAFALAN'!B9 -> DONI SUPRIATNA | E9: =IF(D9>=15,"TERCAPAI","BELUM TERCAPAI") -> BELUM TERCAPAI
A10: 5 | B10: =#REF! -> #REF! | C10: sima'an 15 Juz ( juz 1 - 15 ) | E10: =IF(D10>=15,"TERCAPAI","BELUM TERCAPAI") -> BELUM TERCAPAI
A11: 6 | B11: ='DATA HAFALAN'!B10 -> ZAKY AZHARI | C11: sima'an 13 Juz ( juz 1 - 8, juz 26 - 30 ) | E11: =IF(D11>=13,"TERCAPAI","BELUM TERCAPAI") -> BELUM TERCAPAI
A12: 7 | B12: ='DATA HAFALAN'!B11 -> MUHAMMAD FAUZIL ADZIM | C12: sima'an 25 Juz ( juz 1 - 25 ) | E12: =IF(D12>=25,"TERCAPAI","BELUM TERCAPAI") -> BELUM TERCAPAI
A13: 8 | B13: ='DATA HAFALAN'!B12 -> MUHAMMAD DZIKRI HUSAENI | C13: ziyadah 18 Juz | D13: ='DATA HAFALAN'!C12 -> 18 | E13: =IF(D13>=18,"TERCAPAI","BELUM TERCAPAI") -> TERCAPAI
A14: 9 | B14: =#REF! -> #REF! | C14: ziyadah 15 Juz | D14: =#REF! -> #REF! | E14: =IF(D14>=15,"TERCAPAI","BELUM TERCAPAI") -> #REF!
A15: 10 | B15: ='DATA HAFALAN'!B13 -> ABDUL KHOLIQ | C15: sima'an 10 Juz | E15: =IF(D15>=10,"TERCAPAI","BELUM TERCAPAI") -> BELUM TERCAPAI
A16: 11 | B16: ='DATA HAFALAN'!B14 -> IYAN FARID | C16: ziyadah 12 Juz | D16: ='DATA HAFALAN'!C14 -> 13 | E16: =IF(D16>=12,"TERCAPAI","BELUM TERCAPAI") -> TERCAPAI
A17: 12 | B17: ='DATA HAFALAN'!B15 -> ZAENI NURIL HIKAM | C17: ziyadah 12 Juz | D17: ='DATA HAFALAN'!C15 -> 12 | E17: =IF(D17>=12,"TERCAPAI","BELUM TERCAPAI") -> TERCAPAI
A18: 13 | B18: ='DATA HAFALAN'!B16 -> LUCKY KURNIAWAN | D18: ='DATA HAFALAN'!C16 -> 12 | E18: =IF(D18>=15,"TERCAPAI","BELUM TERCAPAI") -> BELUM TERCAPAI
A19: 14 | B19: ='DATA HAFALAN'!B17 -> MUHAMMAD RAFIK MUHARAM | C19: ziyadah 10 Juz | D19: ='DATA HAFALAN'!C17 -> 12 | E19: =IF(D19>=10,"TERCAPAI","BELUM TERCAPAI") -> TERCAPAI
A20: 15 | B20: ='DATA HAFALAN'!B18 -> UMAR ABDUL MALIK | C20: ziyadah sampe juz 6 | D20: ='DATA HAFALAN'!C18 -> 11 | E20: =IF(D20>=8,"TERCAPAI","BELUM TERCAPAI") -> TERCAPAI
A21: 16 | B21: ='DATA HAFALAN'!B19 -> AHMAD HAFIDZ ALHAWARI | C21: sima'an 6 juz ( ) | E21: =IF(D21>=6,"TERCAPAI","BELUM TERCAPAI") -> BELUM TERCAPAI
A22: 17 | B22: ='DATA HAFALAN'!B20 -> MUHAMMAD FAUZAN | C22: sima'an 5 juz | E22: =IF(D22>=5,"TERCAPAI","BELUM TERCAPAI") -> BELUM TERCAPAI
A23: 18 | B23: ='DATA HAFALAN'!B21 -> AKBAR RAMADAN | C23: ziyadah 5 juz | D23: ='DATA HAFALAN'!C21 -> 9 | E23: =IF(D23>=5,"TERCAPAI","BELUM TERCAPAI") -> TERCAPAI
A24: 19 | B24: =#REF! -> #REF! | C24: ziyadah 5 juz | D24: =#REF! -> #REF! | E24: =IF(D24>=5,"TERCAPAI","BELUM TERCAPAI") -> #REF!
A25: 20 | B25: ='DATA HAFALAN'!B22 -> ABIDZAR ALGHIFARI | C25: ziyadah 4 Juz | D25: ='DATA HAFALAN'!C22 -> 8 | E25: =IF(D25>=4,"TERCAPAI","BELUM TERCAPAI") -> TERCAPAI
A26: 21 | B26: ='DATA HAFALAN'!B23 -> KAFY MUHAMMAD AZIZY | C26: sima'an 2 Juz | E26: =IF(D26>=2,"TERCAPAI","BELUM TERCAPAI") -> BELUM TERCAPAI
A27: 22 | B27: =#REF! -> #REF! | E27: =IF(D27>=15,"TERCAPAI","BELUM TERCAPAI") -> BELUM TERCAPAI
A28: 23 | B28: ='DATA HAFALAN'!B24 -> MUHAMMAD MUNAWWAR KHOLIL | C28: tahap tahsin | E28: =IF(D28="tahap tahsin","TERCAPAI","BELUM TERCAPAI") -> BELUM TERCAPAI
A29: 24 | B29: ='DATA HAFALAN'!B25 -> ALWI | C29: tahap tahsin | E29: =IF(D29>=15,"TERCAPAI","BELUM TERCAPAI") -> BELUM TERCAPAI
A30: 25 | B30: ='DATA HAFALAN'!B26 -> PIRMAN | C30: tahap tahsin | E30: =IF(D30>=15,"TERCAPAI","BELUM TERCAPAI") -> BELUM TERCAPAI
A31: 26 | B31: ='DATA HAFALAN'!B27 -> MUHAMMAD DENMAR NABAWI | C31: tahap tahsin | E31: =IF(D31>=15,"TERCAPAI","BELUM TERCAPAI") -> BELUM TERCAPAI
A32: 27 | B32: =#REF! -> #REF! | C32: tahap tahsin | E32: =IF(D32>=15,"TERCAPAI","BELUM TERCAPAI") -> BELUM TERCAPAI
A33: 28 | B33: =#REF! -> #REF!
A34: 29
A35: 30
A36: 31
A37: 32
A38: 33
A39: 34
A40: 35
A41: 36
A42: 37
A43: 38
...

Sheet jumlah absensi
A1: JUMLAH ABSENSI PERBULAN
A4: ABSENSI NGAJI
A5: NO | B5: NAMA | D5: JUMLAH ABSENSI
C6: HAFALAN | D6: HADIR | E6: SAKIT | F6: IZIN | G6: SEKOLAH | H6: ALPHA
A7: 1 | B7: ='absensi setoran'!B7 -> AYI KOSIM HATIMI | C7: ='absensi setoran'!C7 -> 30 | D7: =SUM(Ngaji!U7,Ngaji!U41,Ngaji!U75,Ngaji!U109,Ngaji!U143) -> 5 | E7: =SUM(Ngaji!V7,Ngaji!V41,Ngaji!V75,Ngaji!V109,Ngaji!V143) -> 0 | F7: =SUM(Ngaji!W7,Ngaji!W41,Ngaji!W75,Ngaji!W109,Ngaji!W143) -> 1 | G7: =SUM(Ngaji!X7,Ngaji!X41,Ngaji!X75,Ngaji!X109,Ngaji!X143) -> 0 | H7: =SUM(Ngaji!Y7,Ngaji!Y41,Ngaji!Y75,Ngaji!Y109,Ngaji!Y143) -> 2 | I7: =B7 -> AYI KOSIM HATIMI
A8: 2 | B8: ='absensi setoran'!B8 -> ABRURRAHMAN AFANDI | C8: ='absensi setoran'!C8 -> 30 | D8: =SUM(Ngaji!U8,Ngaji!U42,Ngaji!U76,Ngaji!U110,Ngaji!U144) -> 3 | E8: =SUM(Ngaji!V8,Ngaji!V42,Ngaji!V76,Ngaji!V110,Ngaji!V144) -> 3 | F8: =SUM(Ngaji!W8,Ngaji!W42,Ngaji!W76,Ngaji!W110,Ngaji!W144) -> 0 | G8: =SUM(Ngaji!X8,Ngaji!X42,Ngaji!X76,Ngaji!X110,Ngaji!X144) -> 0 | H8: =SUM(Ngaji!Y8,Ngaji!Y42,Ngaji!Y76,Ngaji!Y110,Ngaji!Y144) -> 0 | I8: =B8 -> ABRURRAHMAN AFANDI
A9: 3 | B9: ='absensi setoran'!B9 -> CECEP ABDULATIF | C9: ='absensi setoran'!C9 -> 30 | D9: =SUM(Ngaji!U9,Ngaji!U43,Ngaji!U77,Ngaji!U111,Ngaji!U145) -> 8 | E9: =SUM(Ngaji!V9,Ngaji!V43,Ngaji!V77,Ngaji!V111,Ngaji!V145) -> 0 | F9: =SUM(Ngaji!W9,Ngaji!W43,Ngaji!W77,Ngaji!W111,Ngaji!W145) -> 0 | G9: =SUM(Ngaji!X9,Ngaji!X43,Ngaji!X77,Ngaji!X111,Ngaji!X145) -> 0 | H9: =SUM(Ngaji!Y9,Ngaji!Y43,Ngaji!Y77,Ngaji!Y111,Ngaji!Y145) -> 0 | I9: =B9 -> CECEP ABDULATIF
A10: 4 | B10: ='absensi setoran'!B10 -> DONI SUPRIATNA | C10: ='absensi setoran'!C10 -> 30 | D10: =SUM(Ngaji!U10,Ngaji!U44,Ngaji!U78,Ngaji!U112,Ngaji!U146) -> 5 | E10: =SUM(Ngaji!V10,Ngaji!V44,Ngaji!V78,Ngaji!V112,Ngaji!V146) -> 0 | F10: =SUM(Ngaji!W10,Ngaji!W44,Ngaji!W78,Ngaji!W112,Ngaji!W146) -> 3 | G10: =SUM(Ngaji!X10,Ngaji!X44,Ngaji!X78,Ngaji!X112,Ngaji!X146) -> 0 | H10: =SUM(Ngaji!Y10,Ngaji!Y44,Ngaji!Y78,Ngaji!Y112,Ngaji!Y146) -> 0 | I10: =B10 -> DONI SUPRIATNA
A11: 5 | B11: ='absensi setoran'!B11 -> #REF! | C11: ='absensi setoran'!C11 -> #REF! | D11: =SUM(Ngaji!U11,Ngaji!U45,Ngaji!U79,Ngaji!U113,Ngaji!U147) -> 9 | E11: =SUM(Ngaji!V11,Ngaji!V45,Ngaji!V79,Ngaji!V113,Ngaji!V147) -> 0 | F11: =SUM(Ngaji!W11,Ngaji!W45,Ngaji!W79,Ngaji!W113,Ngaji!W147) -> 0 | G11: =SUM(Ngaji!X11,Ngaji!X45,Ngaji!X79,Ngaji!X113,Ngaji!X147) -> 0 | H11: =SUM(Ngaji!Y11,Ngaji!Y45,Ngaji!Y79,Ngaji!Y113,Ngaji!Y147) -> 0 | I11: =B11 -> #REF!
A12: 6 | B12: ='absensi setoran'!B12 -> ZAKY AZHARI | C12: ='absensi setoran'!C12 -> 30 | D12: =SUM(Ngaji!U12,Ngaji!U46,Ngaji!U80,Ngaji!U114,Ngaji!U148) -> 5 | E12: =SUM(Ngaji!V12,Ngaji!V46,Ngaji!V80,Ngaji!V114,Ngaji!V148) -> 0 | F12: =SUM(Ngaji!W12,Ngaji!W46,Ngaji!W80,Ngaji!W114,Ngaji!W148) -> 1 | G12: =SUM(Ngaji!X12,Ngaji!X46,Ngaji!X80,Ngaji!X114,Ngaji!X148) -> 0 | H12: =SUM(Ngaji!Y12,Ngaji!Y46,Ngaji!Y80,Ngaji!Y114,Ngaji!Y148) -> 2 | I12: =B12 -> ZAKY AZHARI
A13: 7 | B13: ='absensi setoran'!B13 -> MUHAMMAD FAUZIL ADZIM | C13: ='absensi setoran'!C13 -> 30 | D13: =SUM(Ngaji!U13,Ngaji!U47,Ngaji!U81,Ngaji!U115,Ngaji!U149) -> 7 | E13: =SUM(Ngaji!V13,Ngaji!V47,Ngaji!V81,Ngaji!V115,Ngaji!V149) -> 0 | F13: =SUM(Ngaji!W13,Ngaji!W47,Ngaji!W81,Ngaji!W115,Ngaji!W149) -> 1 | G13: =SUM(Ngaji!X13,Ngaji!X47,Ngaji!X81,Ngaji!X115,Ngaji!X149) -> 0 | H13: =SUM(Ngaji!Y13,Ngaji!Y47,Ngaji!Y81,Ngaji!Y115,Ngaji!Y149) -> 0 | I13: =B13 -> MUHAMMAD FAUZIL ADZIM
A14: 8 | B14: ='absensi setoran'!B14 -> MUHAMMAD DZIKRI HUSAENI | C14: ='absensi setoran'!C14 -> 18 | D14: =SUM(Ngaji!U14,Ngaji!U48,Ngaji!U82,Ngaji!U116,Ngaji!U150) -> 9 | E14: =SUM(Ngaji!V14,Ngaji!V48,Ngaji!V82,Ngaji!V116,Ngaji!V150) -> 0 | F14: =SUM(Ngaji!W14,Ngaji!W48,Ngaji!W82,Ngaji!W116,Ngaji!W150) -> 0 | G14: =SUM(Ngaji!X14,Ngaji!X48,Ngaji!X82,Ngaji!X116,Ngaji!X150) -> 0 | H14: =SUM(Ngaji!Y14,Ngaji!Y48,Ngaji!Y82,Ngaji!Y116,Ngaji!Y150) -> 0 | I14: =B14 -> MUHAMMAD DZIKRI HUSAENI
A15: 9 | B15: ='absensi setoran'!B15 -> #REF! | C15: ='absensi setoran'!C15 -> #REF! | D15: =SUM(Ngaji!U15,Ngaji!U49,Ngaji!U83,Ngaji!U117,Ngaji!U151) -> 5 | E15: =SUM(Ngaji!V15,Ngaji!V49,Ngaji!V83,Ngaji!V117,Ngaji!V151) -> 0 | F15: =SUM(Ngaji!W15,Ngaji!W49,Ngaji!W83,Ngaji!W117,Ngaji!W151) -> 2 | G15: =SUM(Ngaji!X15,Ngaji!X49,Ngaji!X83,Ngaji!X117,Ngaji!X151) -> 0 | H15: =SUM(Ngaji!Y15,Ngaji!Y49,Ngaji!Y83,Ngaji!Y117,Ngaji!Y151) -> 1 | I15: =B15 -> #REF!
A16: 10 | B16: ='absensi setoran'!B16 -> ABDUL KHOLIQ | C16: ='absensi setoran'!C16 -> 14 | D16: =SUM(Ngaji!U16,Ngaji!U50,Ngaji!U84,Ngaji!U118,Ngaji!U152) -> 8 | E16: =SUM(Ngaji!V16,Ngaji!V50,Ngaji!V84,Ngaji!V118,Ngaji!V152) -> 0 | F16: =SUM(Ngaji!W16,Ngaji!W50,Ngaji!W84,Ngaji!W118,Ngaji!W152) -> 0 | G16: =SUM(Ngaji!X16,Ngaji!X50,Ngaji!X84,Ngaji!X118,Ngaji!X152) -> 0 | H16: =SUM(Ngaji!Y16,Ngaji!Y50,Ngaji!Y84,Ngaji!Y118,Ngaji!Y152) -> 0 | I16: =B16 -> ABDUL KHOLIQ
A17: 11 | B17: ='absensi setoran'!B17 -> IYAN FARID | C17: ='absensi setoran'!C17 -> 13 | D17: =SUM(Ngaji!U17,Ngaji!U51,Ngaji!U85,Ngaji!U119,Ngaji!U153) -> 8 | E17: =SUM(Ngaji!V17,Ngaji!V51,Ngaji!V85,Ngaji!V119,Ngaji!V153) -> 0 | F17: =SUM(Ngaji!W17,Ngaji!W51,Ngaji!W85,Ngaji!W119,Ngaji!W153) -> 0 | G17: =SUM(Ngaji!X17,Ngaji!X51,Ngaji!X85,Ngaji!X119,Ngaji!X153) -> 0 | H17: =SUM(Ngaji!Y17,Ngaji!Y51,Ngaji!Y85,Ngaji!Y119,Ngaji!Y153) -> 0 | I17: =B17 -> IYAN FARID
A18: 12 | B18: ='absensi setoran'!B18 -> ZAENI NURIL HIKAM | C18: ='absensi setoran'!C18 -> 12 | D18: =SUM(Ngaji!U18,Ngaji!U52,Ngaji!U86,Ngaji!U120,Ngaji!U154) -> 8 | E18: =SUM(Ngaji!V18,Ngaji!V52,Ngaji!V86,Ngaji!V120,Ngaji!V154) -> 0 | F18: =SUM(Ngaji!W18,Ngaji!W52,Ngaji!W86,Ngaji!W120,Ngaji!W154) -> 0 | G18: =SUM(Ngaji!X18,Ngaji!X52,Ngaji!X86,Ngaji!X120,Ngaji!X154) -> 0 | H18: =SUM(Ngaji!Y18,Ngaji!Y52,Ngaji!Y86,Ngaji!Y120,Ngaji!Y154) -> 0 | I18: =B18 -> ZAENI NURIL HIKAM
... A30: 24 | B30: ='absensi setoran'!B30 -> ALWI | C30: ='absensi setoran'!C30 -> 3 | D30: =SUM(Ngaji!U30,Ngaji!U64,Ngaji!U98,Ngaji!U132,Ngaji!U166) -> 4 | E30: =SUM(Ngaji!V30,Ngaji!V64,Ngaji!V98,Ngaji!V132,Ngaji!V166) -> 0 | F30: =SUM(Ngaji!W30,Ngaji!W64,Ngaji!W98,Ngaji!W132,Ngaji!W166) -> 0 | G30: =SUM(Ngaji!X30,Ngaji!X64,Ngaji!X98,Ngaji!X132,Ngaji!X166) -> 0 | H30: =SUM(Ngaji!Y30,Ngaji!Y64,Ngaji!Y98,Ngaji!Y132,Ngaji!Y166) -> 0 | I30: =B30 -> ALWI
A31: 25 | B31: ='absensi setoran'!B31 -> PIRMAN
A32: 26 | B32: ='absensi setoran'!B32 -> MUHAMMAD DENMAR NABAWI
A33: 27 | B33: ='absensi setoran'!B33 -> #REF!
A34: 28 | B34: ='absensi setoran'!B34 -> #REF!
A35: JUMLAH ABSENSI PERBULAN
A38: ABSENSI SETORAN
A39: NO | B39: NAMA | D39: JUMLAH ABSENSI
C40: HAFALAN | D40: HADIR | E40: SAKIT | F40: IZIN | G40: SEKOLAH | H40: ALPHA
A41: 1 | B41: ='absensi setoran'!B41 -> AYI KOSIM HATIMI | C41: ='absensi setoran'!C41 -> 30 | D41: =SUM('absensi setoran'!AS7,'absensi setoran'!AS41,'absensi setoran'!AS75,'absensi setoran'!AS109,'absensi setoran'!AS143) -> 11 | E41: =SUM('absensi setoran'!AT7,'absensi setoran'!AT41,'absensi setoran'!AT75,'absensi setoran'!AT109,'absensi setoran'!AT143) -> 0 | F41: =SUM('absensi setoran'!AU7,'absensi setoran'!AU41,'absensi setoran'!AU75,'absensi setoran'!AU109,'absensi setoran'!AU143) -> 2 | G41: =SUM('absensi setoran'!AV7,'absensi setoran'!AV41,'absensi setoran'!AV75,'absensi setoran'!AV109,'absensi setoran'!AV143) -> 0 | H41: =SUM('absensi setoran'!AW7,'absensi setoran'!AW41,'absensi setoran'!AW75,'absensi setoran'!AW109,'absensi setoran'!AW143) -> 3 | I41: =B41 -> AYI KOSIM HATIMI
A42: 2 | B42: ='absensi setoran'!B42 -> ABRURRAHMAN AFANDI | C42: ='absensi setoran'!C42 -> 30 | D42: =SUM('absensi setoran'!AS8,'absensi setoran'!AS42,'absensi setoran'!AS76,'absensi setoran'!AS110,'absensi setoran'!AS144) -> 1 | E42: =SUM('absensi setoran'!AT8,'absensi setoran'!AT42,'absensi setoran'!AT76,'absensi setoran'!AT110,'absensi setoran'!AT144) -> 0 | F42: =SUM('absensi setoran'!AU8,'absensi setoran'!AU42,'absensi setoran'!AU76,'absensi setoran'!AU110,'absensi setoran'!AU144) -> 4 | G42: =SUM('absensi setoran'!AV8,'absensi setoran'!AV42,'absensi setoran'!AV76,'absensi setoran'!AV110,'absensi setoran'!AV144) -> 0 | H42: =SUM('absensi setoran'!AW8,'absensi setoran'!AW42,'absensi setoran'!AW76,'absensi setoran'!AW110,'absensi setoran'!AW144) -> 2 | I42: =B42 -> ABRURRAHMAN AFANDI
A43: 3 | B43: ='absensi setoran'!B43 -> CECEP ABDULATIF | C43: ='absensi setoran'!C43 -> 30 | D43: =SUM('absensi setoran'!AS9,'absensi setoran'!AS43,'absensi setoran'!AS77,'absensi setoran'!AS111,'absensi setoran'!AS145) -> 6 | E43: =SUM('absensi setoran'!AT9,'absensi setoran'!AT43,'absensi setoran'!AT77,'absensi setoran'!AT111,'absensi setoran'!AT145) -> 0 | F43: =SUM('absensi setoran'!AU9,'absensi setoran'!AU43,'absensi setoran'!AU77,'absensi setoran'!AU111,'absensi setoran'!AU145) -> 6 | G43: =SUM('absensi setoran'!AV9,'absensi setoran'!AV43,'absensi setoran'!AV77,'absensi setoran'!AV111,'absensi setoran'!AV145) -> 0 | H43: =SUM('absensi setoran'!AW9,'absensi setoran'!AW43,'absensi setoran'!AW77,'absensi setoran'!AW111,'absensi setoran'!AW145) -> 3 | I43: =B43 -> CECEP ABDULATIF
A44: 4 | B44: ='absensi setoran'!B44 -> DONI SUPRIATNA | C44: ='absensi setoran'!C44 -> 30 | D44: =SUM('absensi setoran'!AS10,'absensi setoran'!AS44,'absensi setoran'!AS78,'absensi setoran'!AS112,'absensi setoran'!AS146) -> 4 | E44: =SUM('absensi setoran'!AT10,'absensi setoran'!AT44,'absensi setoran'!AT78,'absensi setoran'!AT112,'absensi setoran'!AT146) -> 1 | F44: =SUM('absensi setoran'!AU10,'absensi setoran'!AU44,'absensi setoran'!AU78,'absensi setoran'!AU112,'absensi setoran'!AU146) -> 2 | G44: =SUM('absensi setoran'!AV10,'absensi setoran'!AV44,'absensi setoran'!AV78,'absensi setoran'!AV112,'absensi setoran'!AV146) -> 0 | H44: =SUM('absensi setoran'!AW10,'absensi setoran'!AW44,'absensi setoran'!AW78,'absensi setoran'!AW112,'absensi setoran'!AW146) -> 1 | I44: =B44 -> DONI SUPRIATNA
A45: 5 | B45: ='absensi setoran'!B45 -> #REF! | C45: ='absensi setoran'!C45 -> #REF! | D45: =SUM('absensi setoran'!AS11,'absensi setoran'!AS45,'absensi setoran'!AS79,'absensi setoran'!AS113,'absensi setoran'!AS147) -> 11 | E45: =SUM('absensi setoran'!AT11,'absensi setoran'!AT45,'absensi setoran'!AT79,'absensi setoran'!AT113,'absensi setoran'!AT147) -> 0 | F45: =SUM('absensi setoran'!AU11,'absensi setoran'!AU45,'absensi setoran'!AU79,'absensi setoran'!AU113,'absensi setoran'!AU147) -> 0 | G45: =SUM('absensi setoran'!AV11,'absensi setoran'!AV45,'absensi setoran'!AV79,'absensi setoran'!AV113,'absensi setoran'!AV147) -> 0 | H45: =SUM('absensi setoran'!AW11,'absensi setoran'!AW45,'absensi setoran'!AW79,'absensi setoran'!AW113,'absensi setoran'!AW147) -> 2 | I45: =B45 -> #REF!
A46: 6 | B46: ='absensi setoran'!B46 -> ZAKY AZHARI | C46: ='absensi setoran'!C46 -> 30 | D46: =SUM('absensi setoran'!AS12,'absensi setoran'!AS46,'absensi setoran'!AS80,'absensi setoran'!AS114,'absensi setoran'!AS148) -> 2 | E46: =SUM('absensi setoran'!AT12,'absensi setoran'!AT46,'absensi setoran'!AT80,'absensi setoran'!AT114,'absensi setoran'!AT148) -> 3 | F46: =SUM('absensi setoran'!AU12,'absensi setoran'!AU46,'absensi setoran'!AU80,'absensi setoran'!AU114,'absensi setoran'!AU148) -> 1 | G46: =SUM('absensi setoran'!AV12,'absensi setoran'!AV46,'absensi setoran'!AV80,'absensi setoran'!AV114,'absensi setoran'!AV148) -> 2 | H46: =SUM('absensi setoran'!AW12,'absensi setoran'!AW46,'absensi setoran'!AW80,'absensi setoran'!AW114,'absensi setoran'!AW148) -> 3 | I46: =B46 -> ZAKY AZHARI
A47: 7 | B47: ='absensi setoran'!B47 -> MUHAMMAD FAUZIL ADZIM | C47: ='absensi setoran'!C47 -> 30 | D47: =SUM('absensi setoran'!AS13,'absensi setoran'!AS47,'absensi setoran'!AS81,'absensi setoran'!AS115,'absensi setoran'!AS149) -> 12 | E47: =SUM('absensi setoran'!AT13,'absensi setoran'!AT47,'absensi setoran'!AT81,'absensi setoran'!AT115,'absensi setoran'!AT149) -> 0 | F47: =SUM('absensi setoran'!AU13,'absensi setoran'!AU47,'absensi setoran'!AU81,'absensi setoran'!AU115,'absensi setoran'!AU149) -> 0 | G47: =SUM('absensi setoran'!AV13,'absensi setoran'!AV47,'absensi setoran'!AV81,'absensi setoran'!AV115,'absensi setoran'!AV149) -> 0 | H47: =SUM('absensi setoran'!AW13,'absensi setoran'!AW47,'absensi setoran'!AW81,'absensi setoran'!AW115,'absensi setoran'!AW149) -> 0 | I47: =B47 -> MUHAMMAD FAUZIL ADZIM
A48: 8 | B48: ='absensi setoran'!B48 -> MUHAMMAD DZIKRI HUSAENI | C48: ='absensi setoran'!C48 -> 18 | D48: =SUM('absensi setoran'!AS14,'absensi setoran'!AS48,'absensi setoran'!AS82,'absensi setoran'!AS116,'absensi setoran'!AS150) -> 17 | E48: =SUM('absensi setoran'!AT14,'absensi setoran'!AT48,'absensi setoran'!AT82,'absensi setoran'!AT116,'absensi setoran'!AT150) -> 0 | F48: =SUM('absensi setoran'!AU14,'absensi setoran'!AU48,'absensi setoran'!AU82,'absensi setoran'!AU116,'absensi setoran'!AU150) -> 2 | G48: =SUM('absensi setoran'!AV14,'absensi setoran'!AV48,'absensi setoran'!AV82,'absensi setoran'!AV116,'absensi setoran'!AV150) -> 1 | H48: =SUM('absensi setoran'!AW14,'absensi setoran'!AW48,'absensi setoran'!AW82,'absensi setoran'!AW116,'absensi setoran'!AW150) -> 1 | I48: =B48 -> MUHAMMAD DZIKRI HUSAENI
A49: 9 | B49: ='absensi setoran'!B49 -> #REF! | C49: ='absensi setoran'!C49 -> #REF! | D49: =SUM('absensi setoran'!AS15,'absensi setoran'!AS49,'absensi setoran'!AS83,'absensi setoran'!AS117,'absensi setoran'!AS151) -> 15 | E49: =SUM('absensi setoran'!AT15,'absensi setoran'!AT49,'absensi setoran'!AT83,'absensi setoran'!AT117,'absensi setoran'!AT151) -> 0 | F49: =SUM('absensi setoran'!AU15,'absensi setoran'!AU49,'absensi setoran'!AU83,'absensi setoran'!AU117,'absensi setoran'!AU151) -> 4 | G49: =SUM('absensi setoran'!AV15,'absensi setoran'!AV49,'absensi setoran'!AV83,'absensi setoran'!AV117,'absensi setoran'!AV151) -> 0 | H49: =SUM('absensi setoran'!AW15,'absensi setoran'!AW49,'absensi setoran'!AW83,'absensi setoran'!AW117,'absensi setoran'!AW151) -> 3 | I49: =B49 -> #REF!
A50: 10 | B50: ='absensi setoran'!B50 -> ABDUL KHOLIQ | C50: ='absensi setoran'!C50 -> 14 | D50: =SUM('absensi setoran'!AS16,'absensi setoran'!AS50,'absensi setoran'!AS84,'absensi setoran'!AS118,'absensi setoran'!AS152) -> 10 | E50: =SUM('absensi setoran'!AT16,'absensi setoran'!AT50,'absensi setoran'!AT84,'absensi setoran'!AT118,'absensi setoran'!AT152) -> 1 | F50: =SUM('absensi setoran'!AU16,'absensi setoran'!AU50,'absensi setoran'!AU84,'absensi setoran'!AU118,'absensi setoran'!AU152) -> 1 | G50: =SUM('absensi setoran'!AV16,'absensi setoran'!AV50,'absensi setoran'!AV84,'absensi setoran'!AV118,'absensi setoran'!AV152) -> 1 | H50: =SUM('absensi setoran'!AW16,'absensi setoran'!AW50,'absensi setoran'!AW84,'absensi setoran'!AW118,'absensi setoran'!AW152) -> 1 | I50: =B50 -> ABDUL KHOLIQ
A51: 11 | B51: ='absensi setoran'!B51 -> IYAN FARID | C51: ='absensi setoran'!C51 -> 13 | D51: =SUM('absensi setoran'!AS17,'absensi setoran'!AS51,'absensi setoran'!AS85,'absensi setoran'!AS119,'absensi setoran'!AS153) -> 9 | E51: =SUM('absensi setoran'!AT17,'absensi setoran'!AT51,'absensi setoran'!AT85,'absensi setoran'!AT119,'absensi setoran'!AT153) -> 2 | F51: =SUM('absensi setoran'!AU17,'absensi setoran'!AU51,'absensi setoran'!AU85,'absensi setoran'!AU119,'absensi setoran'!AU153) -> 0 | G51: =SUM('absensi setoran'!AV17,'absensi setoran'!AV51,'absensi setoran'!AV85,'absensi setoran'!AV119,'absensi setoran'!AV153) -> 1 | H51: =SUM('absensi setoran'!AW17,'absensi setoran'!AW51,'absensi setoran'!AW85,'absensi setoran'!AW119,'absensi setoran'!AW153) -> 1 | I51: =B51 -> IYAN FARID
A52: 12 | B52: ='absensi setoran'!B52 -> ZAENI NURIL HIKAM | C52: ='absensi setoran'!C52 -> 12 | D52: =SUM('absensi setoran'!AS18,'absensi setoran'!AS52,'absensi setoran'!AS86,'absensi setoran'!AS120,'absensi setoran'!AS154) -> 8 | E52: =SUM('absensi setoran'!AT18,'absensi setoran'!AT52,'absensi setoran'!AT86,'absensi setoran'!AT120,'absensi setoran'!AT154) -> 0 | F52: =SUM('absensi setoran'!AU18,'absensi setoran'!AU52,'absensi setoran'!AU86,'absensi setoran'!AU120,'absensi setoran'!AU154) -> 2 | G52: =SUM('absensi setoran'!AV18,'absensi setoran'!AV52,'absensi setoran'!AV86,'absensi setoran'!AV120,'absensi setoran'!AV154) -> 1 | H52: =SUM('absensi setoran'!AW18,'absensi setoran'!AW52,'absensi setoran'!AW86,'absensi setoran'!AW120,'absensi setoran'!AW154) -> 1 | I52: =B52 -> ZAENI NURIL HIKAM
... A64: 24 | B64: ='absensi setoran'!B64 -> ALWI | C64: ='absensi setoran'!C64 -> 3 | D64: =SUM('absensi setoran'!AS30,'absensi setoran'!AS64,'absensi setoran'!AS98,'absensi setoran'!AS132,'absensi setoran'!AS166) -> 13 | E64: =SUM('absensi setoran'!AT30,'absensi setoran'!AT64,'absensi setoran'!AT98,'absensi setoran'!AT132,'absensi setoran'!AT166) -> 0 | F64: =SUM('absensi setoran'!AU30,'absensi setoran'!AU64,'absensi setoran'!AU98,'absensi setoran'!AU132,'absensi setoran'!AU166) -> 0 | G64: =SUM('absensi setoran'!AV30,'absensi setoran'!AV64,'absensi setoran'!AV98,'absensi setoran'!AV132,'absensi setoran'!AV166) -> 0 | H64: =SUM('absensi setoran'!AW30,'absensi setoran'!AW64,'absensi setoran'!AW98,'absensi setoran'!AW132,'absensi setoran'!AW166) -> 0 | I64: =B64 -> ALWI
A69: JUMLAH ABSENSI PERBULAN
A72: ABSENSI NGAFAL
...

Sheet absensi setoran
A1: ABSENSI SETORAN
A4: MINGGU KE 1
A5: NO | B5: NAMA | D5: Sabtu 2 | K5: Ahad 3 | R5: Senin 4 | Y5: Selasa 5 | AF5: Rabu 6 | AM5: Kamis 7 | AS5: JUMLAH
C6: JUMLAH HAFALAN | D6: PAGI | F6: Penyimak | G6: SIANG | I6: Penyimak | K6: PAGI | M6: Penyimak | N6: SIANG | P6: Penyimak | R6: PAGI | T6: Penyimak | U6: SIANG | W6: Penyimak | Y6: PAGI | AA6: Penyimak | AB6: SIANG | AD6: Penyimak | AF6: PAGI | AH6: Penyimak | AI6: SIANG | AK6: Penyimak | AM6: PAGI | AO6: Penyimak | AP6: SIANG | AR6: Penyimak | AS6: Hadir | AT6: Izin | AU6: Tidur | AV6: Sakit | AW6: Alpha
A7: 1 | B7: ='DATA HAFALAN'!B6 -> AYI KOSIM HATIMI | C7: ='DATA HAFALAN'!C6 -> 30 | J7: =B7 -> AYI KOSIM HATIMI | L7: A | M7: A Rifqi | Q7: =B7 -> AYI KOSIM HATIMI | S7: A | T7: A Rifqi | X7: =B7 -> AYI KOSIM HATIMI | Z7: A | AE7: =B7 -> AYI KOSIM HATIMI | AL7: =B7 -> AYI KOSIM HATIMI | AS7: =COUNTIF(E7:AQ7,"H") -> 0 | AT7: =COUNTIF(E7:AQ7,"I") -> 0 | AU7: =COUNTIF(E7:AQ7,"TD") -> 0 | AV7: =COUNTIF(E7:AQ7,"S") -> 0 | AW7: =COUNTIF(E7:AQ7,"A") -> 3 | AX7: =B7 -> AYI KOSIM HATIMI
A8: 2 | B8: ='DATA HAFALAN'!B7 -> ABRURRAHMAN AFANDI | C8: ='DATA HAFALAN'!C7 -> 30 | J8: =B8 -> ABRURRAHMAN AFANDI | Q8: =B8 -> ABRURRAHMAN AFANDI | X8: =B8 -> ABRURRAHMAN AFANDI | Z8: P | AE8: =B8 -> ABRURRAHMAN AFANDI | AL8: =B8 -> ABRURRAHMAN AFANDI | AS8: =COUNTIF(E8:AQ8,"H") -> 0 | AT8: =COUNTIF(E8:AQ8,"I") -> 0 | AU8: =COUNTIF(E8:AQ8,"TD") -> 0 | AV8: =COUNTIF(E8:AQ8,"S") -> 0 | AW8: =COUNTIF(E8:AQ8,"A") -> 0 | AX8: =B8 -> ABRURRAHMAN AFANDI
A9: 3 | B9: ='DATA HAFALAN'!B8 -> CECEP ABDULATIF | C9: ='DATA HAFALAN'!C8 -> 30 | J9: =B9 -> CECEP ABDULATIF | L9: H | M9: A Rifqi | Q9: =B9 -> CECEP ABDULATIF | X9: =B9 -> CECEP ABDULATIF | Z9: TS | AE9: =B9 -> CECEP ABDULATIF | AL9: =B9 -> CECEP ABDULATIF | AS9: =COUNTIF(E9:AQ9,"H") -> 1 | AT9: =COUNTIF(E9:AQ9,"I") -> 0 | AU9: =COUNTIF(E9:AQ9,"TD") -> 0 | AV9: =COUNTIF(E9:AQ9,"S") -> 0 | AW9: =COUNTIF(E9:AQ9,"A") -> 0 | AX9: =B9 -> CECEP ABDULATIF
A10: 4 | B10: ='DATA HAFALAN'!B9 -> DONI SUPRIATNA | C10: ='DATA HAFALAN'!C9 -> 30 | J10: =B10 -> DONI SUPRIATNA | Q10: =B10 -> DONI SUPRIATNA | X10: =B10 -> DONI SUPRIATNA | Z10: TS | AE10: =B10 -> DONI SUPRIATNA | AL10: =B10 -> DONI SUPRIATNA | AS10: =COUNTIF(E10:AQ10,"H") -> 0 | AT10: =COUNTIF(E10:AQ10,"I") -> 0 | AU10: =COUNTIF(E10:AQ10,"TD") -> 0 | AV10: =COUNTIF(E10:AQ10,"S") -> 0 | AW10: =COUNTIF(E10:AQ10,"A") -> 0 | AX10: =B10 -> DONI SUPRIATNA
A11: 5 | B11: =#REF! -> #REF! | C11: =#REF! -> #REF! | J11: =B11 -> #REF! | L11: TS | M11: A Rifqi | Q11: =B11 -> #REF! | S11: TS | T11: A Rifqi | X11: =B11 -> #REF! | Z11: H | AE11: =B11 -> #REF! | AL11: =B11 -> #REF! | AS11: =COUNTIF(E11:AQ11,"H") -> 1 | AT11: =COUNTIF(E11:AQ11,"I") -> 0 | AU11: =COUNTIF(E11:AQ11,"TD") -> 0 | AV11: =COUNTIF(E11:AQ11,"S") -> 0 | AW11: =COUNTIF(E11:AQ11,"A") -> 0 | AX11: =B11 -> #REF!
A12: 6 | B12: ='DATA HAFALAN'!B10 -> ZAKY AZHARI | C12: ='DATA HAFALAN'!C10 -> 30 | J12: =B12 -> ZAKY AZHARI | L12: TS | M12: A Rifqi | Q12: =B12 -> ZAKY AZHARI | S12: A | T12: A Rifqi | X12: =B12 -> ZAKY AZHARI | Z12: A | AE12: =B12 -> ZAKY AZHARI | AL12: =B12 -> ZAKY AZHARI | AS12: =COUNTIF(E12:AQ12,"H") -> 0 | AT12: =COUNTIF(E12:AQ12,"I") -> 0 | AU12: =COUNTIF(E12:AQ12,"TD") -> 0 | AV12: =COUNTIF(E12:AQ12,"S") -> 0 | AW12: =COUNTIF(E12:AQ12,"A") -> 2 | AX12: =B12 -> ZAKY AZHARI
A13: 7 | B13: ='DATA HAFALAN'!B11 -> MUHAMMAD FAUZIL ADZIM | C13: ='DATA HAFALAN'!C11 -> 30 | J13: =B13 -> MUHAMMAD FAUZIL ADZIM | L13: TS | M13: A Rifqi | Q13: =B13 -> MUHAMMAD FAUZIL ADZIM | S13: TS | T13: A Rifqi | X13: =B13 -> MUHAMMAD FAUZIL ADZIM | Z13: TS | AE13: =B13 -> MUHAMMAD FAUZIL ADZIM | AL13: =B13 -> MUHAMMAD FAUZIL ADZIM | AS13: =COUNTIF(E13:AQ13,"H") -> 0 | AT13: =COUNTIF(E13:AQ13,"I") -> 0 | AU13: =COUNTIF(E13:AQ13,"TD") -> 0 | AV13: =COUNTIF(E13:AQ13,"S") -> 0 | AW13: =COUNTIF(E13:AQ13,"A") -> 0 | AX13: =B13 -> MUHAMMAD FAUZIL ADZIM
A14: 8 | B14: ='DATA HAFALAN'!B12 -> MUHAMMAD DZIKRI HUSAENI | C14: ='DATA HAFALAN'!C12 -> 18 | J14: =B14 -> MUHAMMAD DZIKRI HUSAENI | L14: H | M14: A Rifqi | Q14: =B14 -> MUHAMMAD DZIKRI HUSAENI | S14: H | T14: A Rifqi | X14: =B14 -> MUHAMMAD DZIKRI HUSAENI | Z14: TS | AE14: =B14 -> MUHAMMAD DZIKRI HUSAENI | AL14: =B14 -> MUHAMMAD DZIKRI HUSAENI | AS14: =COUNTIF(E14:AQ14,"H") -> 2 | AT14: =COUNTIF(E14:AQ14,"I") -> 0 | AU14: =COUNTIF(E14:AQ14,"TD") -> 0 | AV14: =COUNTIF(E14:AQ14,"S") -> 0 | AW14: =COUNTIF(E14:AQ14,"A") -> 0 | AX14: =B14 -> MUHAMMAD DZIKRI HUSAENI
A15: 9 | B15: =#REF! -> #REF! | C15: =#REF! -> #REF! | J15: =B15 -> #REF! | L15: H | M15: A Rifqi | Q15: =B15 -> #REF! | S15: TS | T15: A Rifqi | X15: =B15 -> #REF! | Z15: P | AE15: =B15 -> #REF! | AL15: =B15 -> #REF! | AS15: =COUNTIF(E15:AQ15,"H") -> 1 | AT15: =COUNTIF(E15:AQ15,"I") -> 0 | AU15: =COUNTIF(E15:AQ15,"TD") -> 0 | AV15: =COUNTIF(E15:AQ15,"S") -> 0 | AW15: =COUNTIF(E15:AQ15,"A") -> 0 | AX15: =B15 -> #REF!
A16: 10 | B16: ='DATA HAFALAN'!B13 -> ABDUL KHOLIQ | C16: ='DATA HAFALAN'!C13 -> 14 | J16: =B16 -> ABDUL KHOLIQ | L16: TS | M16: A Rifqi | Q16: =B16 -> ABDUL KHOLIQ | S16: H | T16: A Rifqi | X16: =B16 -> ABDUL KHOLIQ | Z16: H | AE16: =B16 -> ABDUL KHOLIQ | AL16: =B16 -> ABDUL KHOLIQ | AS16: =COUNTIF(E16:AQ16,"H") -> 2 | AT16: =COUNTIF(E16:AQ16,"I") -> 0 | AU16: =COUNTIF(E16:AQ16,"TD") -> 0 | AV16: =COUNTIF(E16:AQ16,"S") -> 0 | AW16: =COUNTIF(E16:AQ16,"A") -> 0 | AX16: =B16 -> ABDUL KHOLIQ
A17: 11 | B17: ='DATA HAFALAN'!B14 -> IYAN FARID | C17: ='DATA HAFALAN'!C14 -> 13 | J17: =B17 -> IYAN FARID | L17: H | M17: A Rifqi | Q17: =B17 -> IYAN FARID | S17: H | T17: A Rifqi | X17: =B17 -> IYAN FARID | Z17: H | AE17: =B17 -> IYAN FARID | AL17: =B17 -> IYAN FARID | AS17: =COUNTIF(E17:AQ17,"H") -> 3 | AT17: =COUNTIF(E17:AQ17,"I") -> 0 | AU17: =COUNTIF(E17:AQ17,"TD") -> 0 | AV17: =COUNTIF(E17:AQ17,"S") -> 0 | AW17: =COUNTIF(E17:AQ17,"A") -> 0 | AX17: =B17 -> IYAN FARID
A18: 12 | B18: ='DATA HAFALAN'!B15 -> ZAENI NURIL HIKAM | C18: ='DATA HAFALAN'!C15 -> 12 | J18: =B18 -> ZAENI NURIL HIKAM | L18: H | M18: A Rifqi | Q18: =B18 -> ZAENI NURIL HIKAM | S18: S | T18: A Rifqi | X18: =B18 -> ZAENI NURIL HIKAM | Z18: TS | AE18: =B18 -> ZAENI NURIL HIKAM | AL18: =B18 -> ZAENI NURIL HIKAM | AS18: =COUNTIF(E18:AQ18,"H") -> 1 | AT18: =COUNTIF(E18:AQ18,"I") -> 0 | AU18: =COUNTIF(E18:AQ18,"TD") -> 0 | AV18: =COUNTIF(E18:AQ18,"S") -> 1 | AW18: =COUNTIF(E18:AQ18,"A") -> 0 | AX18: =B18 -> ZAENI NURIL HIKAM
A19: 13 | B19: ='DATA HAFALAN'!B16 -> LUCKY KURNIAWAN | C19: ='DATA HAFALAN'!C16 -> 12 | J19: =B19 -> LUCKY KURNIAWAN | L19: TD | M19: A Rifqi | Q19: =B19 -> LUCKY KURNIAWAN | S19: TD | T19: A Rifqi | X19: =B19 -> LUCKY KURNIAWAN | Z19: TS | AE19: =B19 -> LUCKY KURNIAWAN | AL19: =B19 -> LUCKY KURNIAWAN | AS19: =COUNTIF(E19:AQ19,"H") -> 0 | AT19: =COUNTIF(E19:AQ19,"I") -> 0 | AU19: =COUNTIF(E19:AQ19,"TD") -> 2 | AV19: =COUNTIF(E19:AQ19,"S") -> 0 | AW19: =COUNTIF(E19:AQ19,"A") -> 0 | AX19: =B19 -> LUCKY KURNIAWAN
A20: 14 | B20: ='DATA HAFALAN'!B17 -> MUHAMMAD RAFIK MUHARAM | C20: ='DATA HAFALAN'!C17 -> 12 | J20: =B20 -> MUHAMMAD RAFIK MUHARAM | L20: H | M20: A Rifqi | Q20: =B20 -> MUHAMMAD RAFIK MUHARAM | S20: TD | T20: A Rifqi | X20: =B20 -> MUHAMMAD RAFIK MUHARAM | Z20: TD | AE20: =B20 -> MUHAMMAD RAFIK MUHARAM | AL20: =B20 -> MUHAMMAD RAFIK MUHARAM | AS20: =COUNTIF(E20:AQ20,"H") -> 1 | AT20: =COUNTIF(E20:AQ20,"I") -> 0 | AU20: =COUNTIF(E20:AQ20,"TD") -> 2 | AV20: =COUNTIF(E20:AQ20,"S") -> 0 | AW20: =COUNTIF(E20:AQ20,"A") -> 0 | AX20: =B20 -> MUHAMMAD RAFIK MUHARAM
A21: 15 | B21: ='DATA HAFALAN'!B18 -> UMAR ABDUL MALIK | C21: ='DATA HAFALAN'!C18 -> 11 | J21: =B21 -> UMAR ABDUL MALIK | L21: H | M21: A Rifqi | Q21: =B21 -> UMAR ABDUL MALIK | S21: TS | T21: A Rifqi | X21: =B21 -> UMAR ABDUL MALIK | Z21: TS | AE21: =B21 -> UMAR ABDUL MALIK | AL21: =B21 -> UMAR ABDUL MALIK | AS21: =COUNTIF(E21:AQ21,"H") -> 1 | AT21: =COUNTIF(E21:AQ21,"I") -> 0 | AU21: =COUNTIF(E21:AQ21,"TD") -> 0 | AV21: =COUNTIF(E21:AQ21,"S") -> 0 | AW21: =COUNTIF(E21:AQ21,"A") -> 0 | AX21: =B21 -> UMAR ABDUL MALIK
A22: 16 | B22: ='DATA HAFALAN'!B19 -> AHMAD HAFIDZ ALHAWARI | C22: ='DATA HAFALAN'!C19 -> 10 | J22: =B22 -> AHMAD HAFIDZ ALHAWARI | L22: H | M22: A Rifqi | Q22: =B22 -> AHMAD HAFIDZ ALHAWARI | S22: H | T22: A Rifqi | X22: =B22 -> AHMAD HAFIDZ ALHAWARI | Z22: H | AE22: =B22 -> AHMAD HAFIDZ ALHAWARI | AL22: =B22 -> AHMAD HAFIDZ ALHAWARI | AS22: =COUNTIF(E22:AQ22,"H") -> 3 | AT22: =COUNTIF(E22:AQ22,"I") -> 0 | AU22: =COUNTIF(E22:AQ22,"TD") -> 0 | AV22: =COUNTIF(E22:AQ22,"S") -> 0 | AW22: =COUNTIF(E22:AQ22,"A") -> 0 | AX22: =B22 -> AHMAD HAFIDZ ALHAWARI
A23: 17 | B23: ='DATA HAFALAN'!B20 -> MUHAMMAD FAUZAN | C23: ='DATA HAFALAN'!C20 -> 10 | J23: =B23 -> MUHAMMAD FAUZAN | L23: TS | M23: A Rifqi | Q23: =B23 -> MUHAMMAD FAUZAN | S23: H | T23: A Rifqi | X23: =B23 -> MUHAMMAD FAUZAN | Z23: TS | AE23: =B23 -> MUHAMMAD FAUZAN | AL23: =B23 -> MUHAMMAD FAUZAN | AS23: =COUNTIF(E23:AQ23,"H") -> 1 | AT23: =COUNTIF(E23:AQ23,"I") -> 0 | AU23: =COUNTIF(E23:AQ23,"TD") -> 0 | AV23: =COUNTIF(E23:AQ23,"S") -> 0 | AW23: =COUNTIF(E23:AQ23,"A") -> 0 | AX23: =B23 -> MUHAMMAD FAUZAN
A24: 18 | B24: ='DATA HAFALAN'!B21 -> AKBAR RAMADAN | C24: ='DATA HAFALAN'!C21 -> 9 | J24: =B24 -> AKBAR RAMADAN | L24: TS | M24: A Rifqi | Q24: =B24 -> AKBAR RAMADAN | S24: H | T24: A Rifqi | X24: =B24 -> AKBAR RAMADAN | Z24: H | AE24: =B24 -> AKBAR RAMADAN | AL24: =B24 -> AKBAR RAMADAN | AS24: =COUNTIF(E24:AQ24,"H") -> 2 | AT24: =COUNTIF(E24:AQ24,"I") -> 0 | AU24: =COUNTIF(E24:AQ24,"TD") -> 0 | AV24: =COUNTIF(E24:AQ24,"S") -> 0 | AW24: =COUNTIF(E24:AQ24,"A") -> 0 | AX24: =B24 -> AKBAR RAMADAN
A25: 19 | B25: =#REF! -> #REF! | C25: =#REF! -> #REF! | J25: =B25 -> #REF! | L25: H | M25: A Rifqi | Q25: =B25 -> #REF! | S25: H | T25: A Rifqi | X25: =B25 -> #REF! | Z25: H | AE25: =B25 -> #REF! | AL25: =B25 -> #REF! | AS25: =COUNTIF(E25:AQ25,"H") -> 3 | AT25: =COUNTIF(E25:AQ25,"I") -> 0 | AU25: =COUNTIF(E25:AQ25,"TD") -> 0 | AV25: =COUNTIF(E25:AQ25,"S") -> 0 | AW25: =COUNTIF(E25:AQ25,"A") -> 0 | AX25: =B25 -> #REF!
A26: 20 | B26: ='DATA HAFALAN'!B22 -> ABIDZAR ALGHIFARI | C26: ='DATA HAFALAN'!C22 -> 8 | J26: =B26 -> ABIDZAR ALGHIFARI | L26: H | M26: A Rifqi | Q26: =B26 -> ABIDZAR ALGHIFARI | S26: H | T26: A Rifqi | X26: =B26 -> ABIDZAR ALGHIFARI | Z26: TS | AE26: =B26 -> ABIDZAR ALGHIFARI | AL26: =B26 -> ABIDZAR ALGHIFARI | AS26: =COUNTIF(E26:AQ26,"H") -> 2 | AT26: =COUNTIF(E26:AQ26,"I") -> 0 | AU26: =COUNTIF(E26:AQ26,"TD") -> 0 | AV26: =COUNTIF(E26:AQ26,"S") -> 0 | AW26: =COUNTIF(E26:AQ26,"A") -> 0 | AX26: =B26 -> ABIDZAR ALGHIFARI
A27: 21 | B27: ='DATA HAFALAN'!B23 -> KAFY MUHAMMAD AZIZY | C27: ='DATA HAFALAN'!C23 -> 7 | J27: =B27 -> KAFY MUHAMMAD AZIZY | L27: H | M27: A Rifqi | Q27: =B27 -> KAFY MUHAMMAD AZIZY | S27: H | T27: A Rifqi | X27: =B27 -> KAFY MUHAMMAD AZIZY | Z27: H | AE27: =B27 -> KAFY MUHAMMAD AZIZY | AL27: =B27 -> KAFY MUHAMMAD AZIZY | AS27: =COUNTIF(E27:AQ27,"H") -> 3 | AT27: =COUNTIF(E27:AQ27,"I") -> 0 | AU27: =COUNTIF(E27:AQ27,"TD") -> 0 | AV27: =COUNTIF(E27:AQ27,"S") -> 0 | AW27: =COUNTIF(E27:AQ27,"A") -> 0 | AX27: =B27 -> KAFY MUHAMMAD AZIZY
A28: 22 | B28: =#REF! -> #REF! | C28: =#REF! -> #REF! | J28: =B28 -> #REF! | L28: H | M28: A Rifqi | Q28: =B28 -> #REF! | S28: TS | T28: A Rifqi | X28: =B28 -> #REF! | Z28: TS | AE28: =B28 -> #REF! | AL28: =B28 -> #REF! | AS28: =COUNTIF(E28:AQ28,"H") -> 1 | AT28: =COUNTIF(E28:AQ28,"I") -> 0 | AU28: =COUNTIF(E28:AQ28,"TD") -> 0 | AV28: =COUNTIF(E28:AQ28,"S") -> 0 | AW28: =COUNTIF(E28:AQ28,"A") -> 0 | AX28: =B28 -> #REF!
A29: 23 | B29: ='DATA HAFALAN'!B24 -> MUHAMMAD MUNAWWAR KHOLIL | C29: ='DATA HAFALAN'!C24 -> 4 | J29: =B29 -> MUHAMMAD MUNAWWAR KHOLIL | L29: H | M29: A Rifqi | Q29: =B29 -> MUHAMMAD MUNAWWAR KHOLIL | S29: H | T29: A Rifqi | X29: =B29 -> MUHAMMAD MUNAWWAR KHOLIL | Z29: H | AE29: =B29 -> MUHAMMAD MUNAWWAR KHOLIL | AL29: =B29 -> MUHAMMAD MUNAWWAR KHOLIL | AS29: =COUNTIF(E29:AQ29,"H") -> 3 | AT29: =COUNTIF(E29:AQ29,"I") -> 0 | AU29: =COUNTIF(E29:AQ29,"TD") -> 0 | AV29: =COUNTIF(E29:AQ29,"S") -> 0 | AW29: =COUNTIF(E29:AQ29,"A") -> 0 | AX29: =B29 -> MUHAMMAD MUNAWWAR KHOLIL
A30: 24 | B30: ='DATA HAFALAN'!B25 -> ALWI | C30: ='DATA HAFALAN'!C25 -> 3 | J30: =B30 -> ALWI | Q30: =B30 -> ALWI | X30: =B30 -> ALWI | AE30: =B30 -> ALWI | AL30: =B30 -> ALWI | AS30: =COUNTIF(E30:AQ30,"H") -> 0 | AT30: =COUNTIF(E30:AQ30,"I") -> 0 | AU30: =COUNTIF(E30:AQ30,"TD") -> 0 | AV30: =COUNTIF(E30:AQ30,"S") -> 0 | AW30: =COUNTIF(E30:AQ30,"A") -> 0 | AX30: =B30 -> ALWI
A31: 25 | B31: ='DATA HAFALAN'!B26 -> PIRMAN | C31: ='DATA HAFALAN'!C26 -> 1 | J31: =B31 -> PIRMAN | Q31: =B31 -> PIRMAN | X31: =B31 -> PIRMAN | AE31: =B31 -> PIRMAN | AL31: =B31 -> PIRMAN | AS31: =COUNTIF(E31:AQ31,"H") -> 0 | AT31: =COUNTIF(E31:AQ31,"I") -> 0 | AU31: =COUNTIF(E31:AQ31,"TD") -> 0 | AV31: =COUNTIF(E31:AQ31,"S") -> 0 | AW31: =COUNTIF(E31:AQ31,"A") -> 0 | AX31: =B31 -> PIRMAN
A32: 26 | B32: ='DATA HAFALAN'!B27 -> MUHAMMAD DENMAR NABAWI | C32: ='DATA HAFALAN'!C27 -> 1 | J32: =B32 -> MUHAMMAD DENMAR NABAWI | Q32: =B32 -> MUHAMMAD DENMAR NABAWI | X32: =B32 -> MUHAMMAD DENMAR NABAWI | AE32: =B32 -> MUHAMMAD DENMAR NABAWI | AL32: =B32 -> MUHAMMAD DENMAR NABAWI | AS32: =COUNTIF(E32:AQ32,"H") -> 0 | AT32: =COUNTIF(E32:AQ32,"I") -> 0 | AU32: =COUNTIF(E32:AQ32,"TD") -> 0 | AV32: =COUNTIF(E32:AQ32,"S") -> 0 | AW32: =COUNTIF(E32:AQ32,"A") -> 0 | AX32: =B32 -> MUHAMMAD DENMAR NABAWI
A33: 27 | B33: =#REF! -> #REF! | C33: =#REF! -> #REF! | J33: =B33 -> #REF! | Q33: =B33 -> #REF! | X33: =B33 -> #REF! | AE33: =B33 -> #REF! | AL33: =B33 -> #REF! | AS33: =COUNTIF(E33:AQ33,"H") -> 0 | AT33: =COUNTIF(E33:AQ33,"I") -> 0 | AU33: =COUNTIF(E33:AQ33,"TD") -> 0 | AV33: =COUNTIF(E33:AQ33,"S") -> 0 | AW33: =COUNTIF(E33:AQ33,"A") -> 0 | AX33: =B33 -> #REF!
A34: 28 | B34: =#REF! -> #REF! | C34: =#REF! -> #REF! | J34: =B34 -> #REF! | Q34: =B34 -> #REF! | X34: =B34 -> #REF! | AE34: =B34 -> #REF! | AL34: =B34 -> #REF! | AS34: =COUNTIF(E34:AQ34,"H") -> 0 | AT34: =COUNTIF(E34:AQ34,"I") -> 0 | AU34: =COUNTIF(E34:AQ34,"TD") -> 0 | AV34: =COUNTIF(E34:AQ34,"S") -> 0 | AW34: =COUNTIF(E34:AQ34,"A") -> 0 | AX34: =B34 -> #REF!
A35: ABSENSI SETORAN
A38: MINGGU KE 2
A39: NO | B39: NAMA | D39: SABTU 9 | K39: AHAD 10 | R39: SENIN 11 | Y39: SELASA 12 | AF39: RABU 13 | AM39: KAMIS 14 | AS39: JUMLAH
C40: JUMLAH HAFALAN | D40: SHUBUH | F40: Penyimak | G40: PAGI | I40: Penyimak | K40: SHUBUH | M40: Penyimak | N40: PAGI | P40: Penyimak | R40: SHUBUH | T40: Penyimak | U40: SIANG | W40: Penyimak | Y40: PAGI | AA40: Penyimak | AB40: SIANG | AD40: Penyimak | AF40: SHUBUH | AH40: Penyimak | AI40: PAGI | AK40: Penyimak | AM40: SHUBUH | AO40: Penyimak | AP40: PAGI | AR40: Penyimak | AS40: Hadir | AT40: Izin | AU40: Tidur | AV40: Sakit | AW40: Alpha
A41: 1 | B41: =B7 -> AYI KOSIM HATIMI | C41: =C7 -> 30 | E41: H | F41: A Rifqi | H41: H | J41: =B41 -> AYI KOSIM HATIMI | Q41: =B41 -> AYI KOSIM HATIMI | R41: juz 13 ¼ | S41: H | T41: A Rifqi | X41: =B41 -> AYI KOSIM HATIMI | AE41: =B41 -> AYI KOSIM HATIMI | AG41: TD | AI41: فلما أن جاء البشير | AJ41: H | AK41: A Rifqi | AL41: =B41 -> AYI KOSIM HATIMI | AN41: TS | AQ41: TD | AS41: =COUNTIF(E41:AQ41,"H") -> 4 | AT41: =COUNTIF(E41:AQ41,"I") -> 0 | AU41: =COUNTIF(E41:AQ41,"TD") -> 2 | AV41: =COUNTIF(E41:AQ41,"S") -> 0 | AW41: =COUNTIF(E41:AQ41,"A") -> 0 | AX41: =B41 -> AYI KOSIM HATIMI
A42: 2 | B42: =B8 -> ABRURRAHMAN AFANDI | C42: =C8 -> 30 | E42: P | H42: P | J42: =B42 -> ABRURRAHMAN AFANDI | Q42: =B42 -> ABRURRAHMAN AFANDI | S42: P | X42: =B42 -> ABRURRAHMAN AFANDI | AE42: =B42 -> ABRURRAHMAN AFANDI | AG42: P | AJ42: P | AL42: =B42 -> ABRURRAHMAN AFANDI | AN42: P | AQ42: P | AS42: =COUNTIF(E42:AQ42,"H") -> 0 | AT42: =COUNTIF(E42:AQ42,"I") -> 0 | AU42: =COUNTIF(E42:AQ42,"TD") -> 0 | AV42: =COUNTIF(E42:AQ42,"S") -> 0 | AW42: =COUNTIF(E42:AQ42,"A") -> 0 | AX42: =B42 -> ABRURRAHMAN AFANDI
A43: 3 | B43: =B9 -> CECEP ABDULATIF | C43: =C9 -> 30 | E43: H | F43: A Rifqi | H43: H | J43: =B43 -> CECEP ABDULATIF | Q43: =B43 -> CECEP ABDULATIF | R43: فإذا جآءتهم الحسنة قالوا لنا هذه | S43: H | T43: A Rifqi | X43: =B43 -> CECEP ABDULATIF | AE43: =B43 -> CECEP ABDULATIF | AG43: TD | AJ43: TD | AL43: =B43 -> CECEP ABDULATIF | AN43: TD | AQ43: TD | AS43: =COUNTIF(E43:AQ43,"H") -> 3 | AT43: =COUNTIF(E43:AQ43,"I") -> 0 | AU43: =COUNTIF(E43:AQ43,"TD") -> 4 | AV43: =COUNTIF(E43:AQ43,"S") -> 0 | AW43: =COUNTIF(E43:AQ43,"A") -> 0 | AX43: =B43 -> CECEP ABDULATIF
A44: 4 | B44: =B10 -> DONI SUPRIATNA | C44: =C10 -> 30 | E44: H | F44: A Rifqi | H44: H | J44: =B44 -> DONI SUPRIATNA | Q44: =B44 -> DONI SUPRIATNA | S44: TS | X44: =B44 -> DONI SUPRIATNA | AE44: =B44 -> DONI SUPRIATNA | AG44: TD | AJ44: H | AL44: =B44 -> DONI SUPRIATNA | AN44: TS | AQ44: TD | AS44: =COUNTIF(E44:AQ44,"H") -> 3 | AT44: =COUNTIF(E44:AQ44,"I") -> 0 | AU44: =COUNTIF(E44:AQ44,"TD") -> 2 | AV44: =COUNTIF(E44:AQ44,"S") -> 0 | AW44: =COUNTIF(E44:AQ44,"A") -> 0 | AX44: =B44 -> DONI SUPRIATNA
...

Sheet Ngaji
A1: ABSENSI NGAJI
A4: MINGGU Ke 1
A5: NO | B5: NAMA | D5: SABTU 2 | F5: NAMA | G5: AHAD 3 | I5: NAMA | J5: SENIN 4 | L5: NAMA | M5: SELASA 5 | O5: NAMA | P5: RABU 6 | R5: NAMA | S5: KAMIS 7 | U5: JUMLAH ABSENSI
C6: HAFALAN | D6: MALAM | E6: PAGI | G6: MALAM | H6: PAGI | J6: MALAM | K6: PAGI | M6: MALAM | N6: PAGI | P6: MALAM | Q6: PAGI | S6: MALAM | T6: PAGI | U6: HADIR | V6: SAKIT | W6: IZIN | X6: SEKOLAH | Y6: ALPHA
A7: 1 | B7: ='absensi setoran'!B7 -> AYI KOSIM HATIMI | C7: ='absensi setoran'!C7 -> 30 | F7: =B7 -> AYI KOSIM HATIMI | I7: =B7 -> AYI KOSIM HATIMI | J7: A | L7: =B7 -> AYI KOSIM HATIMI | M7: A | O7: =B7 -> AYI KOSIM HATIMI | R7: =B7 -> AYI KOSIM HATIMI | U7: =COUNTIF(B7:T7,"H") -> 0 | V7: =COUNTIF(B7:T7,"ST") -> 0 | W7: =COUNTIF(B7:T7,"I") -> 0 | X7: =COUNTIF(B7:T7,"S") -> 0 | Y7: =COUNTIF(B7:T7,"A") -> 2 | Z7: =B7 -> AYI KOSIM HATIMI
A8: 2 | B8: ='absensi setoran'!B8 -> ABRURRAHMAN AFANDI | C8: ='absensi setoran'!C8 -> 30 | F8: =B8 -> ABRURRAHMAN AFANDI | I8: =B8 -> ABRURRAHMAN AFANDI | L8: =B8 -> ABRURRAHMAN AFANDI | O8: =B8 -> ABRURRAHMAN AFANDI | R8: =B8 -> ABRURRAHMAN AFANDI | U8: =COUNTIF(B8:T8,"H") -> 0 | V8: =COUNTIF(B8:T8,"ST") -> 0 | W8: =COUNTIF(B8:T8,"I") -> 0 | X8: =COUNTIF(B8:T8,"S") -> 0 | Y8: =COUNTIF(B8:T8,"A") -> 0 | Z8: =B8 -> ABRURRAHMAN AFANDI
A9: 3 | B9: ='absensi setoran'!B9 -> CECEP ABDULATIF | C9: ='absensi setoran'!C9 -> 30 | F9: =B9 -> CECEP ABDULATIF | I9: =B9 -> CECEP ABDULATIF | J9: H | L9: =B9 -> CECEP ABDULATIF | M9: H | O9: =B9 -> CECEP ABDULATIF | R9: =B9 -> CECEP ABDULATIF | U9: =COUNTIF(B9:T9,"H") -> 2 | V9: =COUNTIF(B9:T9,"ST") -> 0 | W9: =COUNTIF(B9:T9,"I") -> 0 | X9: =COUNTIF(B9:T9,"S") -> 0 | Y9: =COUNTIF(B9:T9,"A") -> 0 | Z9: =B9 -> CECEP ABDULATIF
A10: 4 | B10: ='absensi setoran'!B10 -> DONI SUPRIATNA | C10: ='absensi setoran'!C10 -> 30 | F10: =B10 -> DONI SUPRIATNA | I10: =B10 -> DONI SUPRIATNA | L10: =B10 -> DONI SUPRIATNA | M10: H | O10: =B10 -> DONI SUPRIATNA | R10: =B10 -> DONI SUPRIATNA | U10: =COUNTIF(B10:T10,"H") -> 1 | V10: =COUNTIF(B10:T10,"ST") -> 0 | W10: =COUNTIF(B10:T10,"I") -> 0 | X10: =COUNTIF(B10:T10,"S") -> 0 | Y10: =COUNTIF(B10:T10,"A") -> 0 | Z10: =B10 -> DONI SUPRIATNA
A11: 5 | B11: ='absensi setoran'!B11 -> #REF! | C11: ='absensi setoran'!C11 -> #REF! | F11: =B11 -> #REF! | I11: =B11 -> #REF! | J11: H | L11: =B11 -> #REF! | M11: H | O11: =B11 -> #REF! | R11: =B11 -> #REF! | U11: =COUNTIF(B11:T11,"H") -> 2 | V11: =COUNTIF(B11:T11,"ST") -> 0 | W11: =COUNTIF(B11:T11,"I") -> 0 | X11: =COUNTIF(B11:T11,"S") -> 0 | Y11: =COUNTIF(B11:T11,"A") -> 0 | Z11: =B11 -> #REF!
A12: 6 | B12: ='absensi setoran'!B12 -> ZAKY AZHARI | C12: ='absensi setoran'!C12 -> 30 | F12: =B12 -> ZAKY AZHARI | I12: =B12 -> ZAKY AZHARI | J12: A | L12: =B12 -> ZAKY AZHARI | M12: A | O12: =B12 -> ZAKY AZHARI | R12: =B12 -> ZAKY AZHARI | U12: =COUNTIF(B12:T12,"H") -> 0 | V12: =COUNTIF(B12:T12,"ST") -> 0 | W12: =COUNTIF(B12:T12,"I") -> 0 | X12: =COUNTIF(B12:T12,"S") -> 0 | Y12: =COUNTIF(B12:T12,"A") -> 2 | Z12: =B12 -> ZAKY AZHARI
A13: 7 | B13: ='absensi setoran'!B13 -> MUHAMMAD FAUZIL ADZIM | C13: ='absensi setoran'!C13 -> 30 | F13: =B13 -> MUHAMMAD FAUZIL ADZIM | I13: =B13 -> MUHAMMAD FAUZIL ADZIM | J13: H | L13: =B13 -> MUHAMMAD FAUZIL ADZIM | M13: H | O13: =B13 -> MUHAMMAD FAUZIL ADZIM | R13: =B13 -> MUHAMMAD FAUZIL ADZIM | U13: =COUNTIF(B13:T13,"H") -> 2 | V13: =COUNTIF(B13:T13,"ST") -> 0 | W13: =COUNTIF(B13:T13,"I") -> 0 | X13: =COUNTIF(B13:T13,"S") -> 0 | Y13: =COUNTIF(B13:T13,"A") -> 0 | Z13: =B13 -> MUHAMMAD FAUZIL ADZIM
A14: 8 | B14: ='absensi setoran'!B14 -> MUHAMMAD DZIKRI HUSAENI | C14: ='absensi setoran'!C14 -> 18 | F14: =B14 -> MUHAMMAD DZIKRI HUSAENI | I14: =B14 -> MUHAMMAD DZIKRI HUSAENI | J14: H | L14: =B14 -> MUHAMMAD DZIKRI HUSAENI | M14: H | O14: =B14 -> MUHAMMAD DZIKRI HUSAENI | R14: =B14 -> MUHAMMAD DZIKRI HUSAENI | U14: =COUNTIF(B14:T14,"H") -> 2 | V14: =COUNTIF(B14:T14,"ST") -> 0 | W14: =COUNTIF(B14:T14,"I") -> 0 | X14: =COUNTIF(B14:T14,"S") -> 0 | Y14: =COUNTIF(B14:T14,"A") -> 0 | Z14: =B14 -> MUHAMMAD DZIKRI HUSAENI
A15: 9 | B15: ='absensi setoran'!B15 -> #REF! | C15: ='absensi setoran'!C15 -> #REF! | F15: =B15 -> #REF! | I15: =B15 -> #REF! | J15: H | L15: =B15 -> #REF! | M15: I | O15: =B15 -> #REF! | R15: =B15 -> #REF! | U15: =COUNTIF(B15:T15,"H") -> 1 | V15: =COUNTIF(B15:T15,"ST") -> 0 | W15: =COUNTIF(B15:T15,"I") -> 1 | X15: =COUNTIF(B15:T15,"S") -> 0 | Y15: =COUNTIF(B15:T15,"A") -> 0 | Z15: =B15 -> #REF!
A16: 10 | B16: ='absensi setoran'!B16 -> ABDUL KHOLIQ | C16: ='absensi setoran'!C16 -> 14 | F16: =B16 -> ABDUL KHOLIQ | I16: =B16 -> ABDUL KHOLIQ | J16: H | L16: =B16 -> ABDUL KHOLIQ | M16: H | O16: =B16 -> ABDUL KHOLIQ | R16: =B16 -> ABDUL KHOLIQ | U16: =COUNTIF(B16:T16,"H") -> 2 | V16: =COUNTIF(B16:T16,"ST") -> 0 | W16: =COUNTIF(B16:T16,"I") -> 0 | X16: =COUNTIF(B16:T16,"S") -> 0 | Y16: =COUNTIF(B16:T16,"A") -> 0 | Z16: =B16 -> ABDUL KHOLIQ
A17: 11 | B17: ='absensi setoran'!B17 -> IYAN FARID | C17: ='absensi setoran'!C17 -> 13 | F17: =B17 -> IYAN FARID | I17: =B17 -> IYAN FARID | J17: H | L17: =B17 -> IYAN FARID | M17: H | O17: =B17 -> IYAN FARID | R17: =B17 -> IYAN FARID | U17: =COUNTIF(B17:T17,"H") -> 2 | V17: =COUNTIF(B17:T17,"ST") -> 0 | W17: =COUNTIF(B17:T17,"I") -> 0 | X17: =COUNTIF(B17:T17,"S") -> 0 | Y17: =COUNTIF(B17:T17,"A") -> 0 | Z17: =B17 -> IYAN FARID
A18: 12 | B18: ='absensi setoran'!B18 -> ZAENI NURIL HIKAM | C18: ='absensi setoran'!C18 -> 12 | F18: =B18 -> ZAENI NURIL HIKAM | I18: =B18 -> ZAENI NURIL HIKAM | J18: H | L18: =B18 -> ZAENI NURIL HIKAM | M18: H | O18: =B18 -> ZAENI NURIL HIKAM | R18: =B18 -> ZAENI NURIL HIKAM | U18: =COUNTIF(B18:T18,"H") -> 2 | V18: =COUNTIF(B18:T18,"ST") -> 0 | W18: =COUNTIF(B18:T18,"I") -> 0 | X18: =COUNTIF(B18:T18,"S") -> 0 | Y18: =COUNTIF(B18:T18,"A") -> 0 | Z18: =B18 -> ZAENI NURIL HIKAM
A19: 13 | B19: ='absensi setoran'!B19 -> LUCKY KURNIAWAN | C19: ='absensi setoran'!C19 -> 12 | F19: =B19 -> LUCKY KURNIAWAN | I19: =B19 -> LUCKY KURNIAWAN | J19: H | L19: =B19 -> LUCKY KURNIAWAN | M19: H | O19: =B19 -> LUCKY KURNIAWAN | R19: =B19 -> LUCKY KURNIAWAN | U19: =COUNTIF(B19:T19,"H") -> 2 | V19: =COUNTIF(B19:T19,"ST") -> 0 | W19: =COUNTIF(B19:T19,"I") -> 0 | X19: =COUNTIF(B19:T19,"S") -> 0 | Y19: =COUNTIF(B19:T19,"A") -> 0 | Z19: =B19 -> LUCKY KURNIAWAN
A20: 14 | B20: ='absensi setoran'!B20 -> MUHAMMAD RAFIK MUHARAM | C20: ='absensi setoran'!C20 -> 12 | F20: =B20 -> MUHAMMAD RAFIK MUHARAM | I20: =B20 -> MUHAMMAD RAFIK MUHARAM | J20: H | L20: =B20 -> MUHAMMAD RAFIK MUHARAM | M20: H | O20: =B20 -> MUHAMMAD RAFIK MUHARAM | R20: =B20 -> MUHAMMAD RAFIK MUHARAM | U20: =COUNTIF(B20:T20,"H") -> 2 | V20: =COUNTIF(B20:T20,"ST") -> 0 | W20: =COUNTIF(B20:T20,"I") -> 0 | X20: =COUNTIF(B20:T20,"S") -> 0 | Y20: =COUNTIF(B20:T20,"A") -> 0 | Z20: =B20 -> MUHAMMAD RAFIK MUHARAM
A21: 15 | B21: ='absensi setoran'!B21 -> UMAR ABDUL MALIK | C21: ='absensi setoran'!C21 -> 11 | F21: =B21 -> UMAR ABDUL MALIK | I21: =B21 -> UMAR ABDUL MALIK | J21: H | L21: =B21 -> UMAR ABDUL MALIK | M21: H | O21: =B21 -> UMAR ABDUL MALIK | R21: =B21 -> UMAR ABDUL MALIK | U21: =COUNTIF(B21:T21,"H") -> 2 | V21: =COUNTIF(B21:T21,"ST") -> 0 | W21: =COUNTIF(B21:T21,"I") -> 0 | X21: =COUNTIF(B21:T21,"S") -> 0 | Y21: =COUNTIF(B21:T21,"A") -> 0 | Z21: =B21 -> UMAR ABDUL MALIK
A22: 16 | B22: ='absensi setoran'!B22 -> AHMAD HAFIDZ ALHAWARI | C22: ='absensi setoran'!C22 -> 10 | F22: =B22 -> AHMAD HAFIDZ ALHAWARI | I22: =B22 -> AHMAD HAFIDZ ALHAWARI | J22: H | L22: =B22 -> AHMAD HAFIDZ ALHAWARI | M22: H | O22: =B22 -> AHMAD HAFIDZ ALHAWARI | R22: =B22 -> AHMAD HAFIDZ ALHAWARI | U22: =COUNTIF(B22:T22,"H") -> 2 | V22: =COUNTIF(B22:T22,"ST") -> 0 | W22: =COUNTIF(B22:T22,"I") -> 0 | X22: =COUNTIF(B22:T22,"S") -> 0 | Y22: =COUNTIF(B22:T22,"A") -> 0 | Z22: =B22 -> AHMAD HAFIDZ ALHAWARI
... A29: 23 | B29: ='absensi setoran'!B29 -> MUHAMMAD MUNAWWAR KHOLIL | C29: ='absensi setoran'!C29 -> 4 | F29: =B29 -> MUHAMMAD MUNAWWAR KHOLIL | I29: =B29 -> MUHAMMAD MUNAWWAR KHOLIL | J29: H | L29: =B29 -> MUHAMMAD MUNAWWAR KHOLIL | M29: H | O29: =B29 -> MUHAMMAD MUNAWWAR KHOLIL | R29: =B29 -> MUHAMMAD MUNAWWAR KHOLIL | U29: =COUNTIF(B29:T29,"H") -> 2 | V29: =COUNTIF(B29:T29,"ST") -> 0 | W29: =COUNTIF(B29:T29,"I") -> 0 | X29: =COUNTIF(B29:T29,"S") -> 0 | Y29: =COUNTIF(B29:T29,"A") -> 0 | Z29: =B29 -> MUHAMMAD MUNAWWAR KHOLIL
A30: 24 | B30: ='absensi setoran'!B30 -> ALWI | C30: ='absensi setoran'!C30 -> 3 | F30: =B30 -> ALWI | I30: =B30 -> ALWI | L30: =B30 -> ALWI | O30: =B30 -> ALWI | R30: =B30 -> ALWI | U30: =COUNTIF(B30:T30,"H") -> 0 | V30: =COUNTIF(B30:T30,"ST") -> 0 | W30: =COUNTIF(B30:T30,"I") -> 0 | X30: =COUNTIF(B30:T30,"S") -> 0 | Y30: =COUNTIF(B30:T30,"A") -> 0 | Z30: =B30 -> ALWI
A31: 25 | B31: ='absensi setoran'!B31 -> PIRMAN | C31: ='absensi setoran'!C31 -> 1 | F31: =B31 -> PIRMAN | I31: =B31 -> PIRMAN | L31: =B31 -> PIRMAN | O31: =B31 -> PIRMAN | R31: =B31 -> PIRMAN | U31: =COUNTIF(B31:T31,"H") -> 0 | V31: =COUNTIF(B31:T31,"ST") -> 0 | W31: =COUNTIF(B31:T31,"I") -> 0 | X31: =COUNTIF(B31:T31,"S") -> 0 | Y31: =COUNTIF(B31:T31,"A") -> 0 | Z31: =B31 -> PIRMAN
A32: 26 | B32: ='absensi setoran'!B32 -> MUHAMMAD DENMAR NABAWI | C32: ='absensi setoran'!C32 -> 1 | F32: =B32 -> MUHAMMAD DENMAR NABAWI | I32: =B32 -> MUHAMMAD DENMAR NABAWI | L32: =B32 -> MUHAMMAD DENMAR NABAWI | O32: =B32 -> MUHAMMAD DENMAR NABAWI | R32: =B32 -> MUHAMMAD DENMAR NABAWI | U32: =COUNTIF(B32:T32,"H") -> 0 | V32: =COUNTIF(B32:T32,"ST") -> 0 | W32: =COUNTIF(B32:T32,"I") -> 0 | X32: =COUNTIF(B32:T32,"S") -> 0 | Y32: =COUNTIF(B32:T32,"A") -> 0 | Z32: =B32 -> MUHAMMAD DENMAR NABAWI
A33: 27 | B33: ='absensi setoran'!B33 -> #REF! | C33: ='absensi setoran'!C33 -> #REF! | F33: =B33 -> #REF! | I33: =B33 -> #REF! | L33: =B33 -> #REF! | O33: =B33 -> #REF! | R33: =B33 -> #REF! | U33: =COUNTIF(B33:T33,"H") -> 0 | V33: =COUNTIF(B33:T33,"ST") -> 0 | W33: =COUNTIF(B33:T33,"I") -> 0 | X33: =COUNTIF(B33:T33,"S") -> 0 | Y33: =COUNTIF(B33:T33,"A") -> 0 | Z33: =B33 -> #REF!
A34: 28 | B34: ='absensi setoran'!B34 -> #REF! | C34: ='absensi setoran'!C34 -> #REF! | F34: =B34 -> #REF! | I34: =B34 -> #REF! | L34: =B34 -> #REF! | O34: =B34 -> #REF! | R34: =B34 -> #REF! | U34: =COUNTIF(B34:T34,"H") -> 0 | V34: =COUNTIF(B34:T34,"ST") -> 0 | W34: =COUNTIF(B34:T34,"I") -> 0 | X34: =COUNTIF(B34:T34,"S") -> 0 | Y34: =COUNTIF(B34:T34,"A") -> 0 | Z34: =B34 -> #REF!
A35: ABSENSI NGAJI
A38: MINGGU Ke 2
A39: NO | B39: NAMA | D39: SABTU 9 | F39: NAMA | G39: AHAD 10 | I39: NAMA | J39: SENIN 11 | L39: NAMA | M39: SELASA 12 | O39: NAMA | P39: RABU 13 | R39: NAMA | S39: KAMIS 14 | U39: JUMLAH ABSENSI
C40: HAFALAN | D40: MALAM | E40: SIANG | G40: MALAM | H40: PAGI | J40: MALAM | K40: PAGI | M40: MALAM | N40: PAGI | P40: MALAM | Q40: PAGI | S40: MALAM | T40: PAGI | U40: HADIR | V40: SAKIT | W40: IZIN | X40: SEKOLAH | Y40: ALPHA
A41: 1 | B41: ='absensi setoran'!B41 -> AYI KOSIM HATIMI | C41: ='absensi setoran'!C41 -> 30 | D41: I | F41: =B41 -> AYI KOSIM HATIMI | G41: H | I41: =B41 -> AYI KOSIM HATIMI | J41: H | L41: =B41 -> AYI KOSIM HATIMI | O41: =B41 -> AYI KOSIM HATIMI | R41: =B41 -> AYI KOSIM HATIMI | U41: =COUNTIF(B41:T41,"H") -> 2 | V41: =COUNTIF(B41:T41,"ST") -> 0 | W41: =COUNTIF(B41:T41,"I") -> 1 | X41: =COUNTIF(B41:T41,"S") -> 0 | Y41: =COUNTIF(B41:T41,"A") -> 0 | Z41: =B41 -> AYI KOSIM HATIMI
A42: 2 | B42: ='absensi setoran'!B42 -> ABRURRAHMAN AFANDI | C42: ='absensi setoran'!C42 -> 30 | D42: ST | F42: =B42 -> ABRURRAHMAN AFANDI | G42: ST | I42: =B42 -> ABRURRAHMAN AFANDI | J42: ST | L42: =B42 -> ABRURRAHMAN AFANDI | O42: =B42 -> ABRURRAHMAN AFANDI | R42: =B42 -> ABRURRAHMAN AFANDI | U42: =COUNTIF(B42:T42,"H") -> 0 | V42: =COUNTIF(B42:T42,"ST") -> 3 | W42: =COUNTIF(B42:T42,"I") -> 0 | X42: =COUNTIF(B42:T42,"S") -> 0 | Y42: =COUNTIF(B42:T42,"A") -> 0 | Z42: =B42 -> ABRURRAHMAN AFANDI
